Workbook

Sheet 01 Tổng quan
A1: Bộ dữ liệu tài chính NIKE, Inc. FY2020–FY2026
A2: Cơ sở số liệu cho đề tài “Đổi mới và tái cân bằng chiến lược phân phối tại Nike: Từ Direct-to-Consumer (D2C) đến bán buôn và những biến động tài chính giai đoạn FY2020–FY2026”.
A4: Thông tin chung
A5: Mục đích | B5: Tập hợp số liệu chính thức về doanh thu theo kênh phân phối (NIKE Direct, bán buôn) và kết quả tài chính hợp nhất của NIKE, Inc. để nhóm dùng trong báo cáo, thuyết trình và dashboard.
A6: Kỳ nghiên cứu | B6: FY2020–FY2026. Năm tài chính của NIKE kết thúc ngày 31/5, ví dụ FY2026 = 01/06/2025 – 31/05/2026. FY không trùng với năm dương lịch.
A7: Đơn vị | B7: Triệu USD, trừ khi cột “Đơn vị” ghi khác (tỷ USD cho doanh số Digital; % cho tỷ lệ). Không quy đổi sang VND.
A8: Nguồn | B8: 7 báo cáo thường niên Form 10-K của NIKE, Inc. nộp Ủy ban Chứng khoán Mỹ (SEC), FY2020–FY2026. Không dùng trang tổng hợp tài chính của bên thứ ba.
A9: Thứ tự ưu tiên nguồn | B9: (1) Báo cáo tài chính đã kiểm toán và thuyết minh (Item 8), lấy từ dữ liệu XBRL đi kèm chính báo cáo 10-K. (2) Phần MD&A (Item 7) của cùng báo cáo, cho các số non-GAAP và số do ban điều hành nêu: EBIT, tăng trưởng loại trừ tỷ giá, doanh số Digital. (3) Dữ liệu XBRL do SEC công bố chỉ dùng để đối chiếu.
A10: Quy tắc chọn số | B10: Số liệu của mỗi năm tài chính được lấy từ báo cáo 10-K của chính năm đó. “Giá trị năm trước” là số của năm trước được in kèm trong cùng báo cáo để so sánh, dùng để tính tăng trưởng giống cách NIKE tự tính. Nếu báo cáo năm sau trình bày lại số liệu, phần chênh lệch được ghi ở cột “Trình bày lại ở 10-K sau”, số gốc giữ nguyên.
A11: Tình trạng dữ liệu | B11: Trích xuất tự động ngày 23/10/2026. 203 số liệu: 202 khớp nguồn chính thức, 1 không được công bố.
A13: Cách sử dụng
A14: 1. Đọc số liệu | B14: Sheet 02 (hợp nhất NIKE, Inc.) và 03 (kênh phân phối NIKE Brand). Mỗi dòng là một số liệu của một năm. Dùng nút lọc ở dòng tiêu đề để chọn chỉ tiêu hoặc năm.
A15: 2. Kiểm tra nguồn | B15: Bấm liên kết ở cột “Tài liệu nguồn” để mở 10-K trên SEC EDGAR. Tìm số trang ở cột “Trang” (số in ở chân trang, dạng “2026 FORM 10-K 83”) rồi đối chiếu với cột “Số hoặc câu hiển thị trong tài liệu”.
A16: 3. Ghi nhận xác minh | B16: Sau khi tự đối chiếu, chọn “Đã xác minh (người)” ở cột “Trạng thái dữ liệu” và điền tên, ngày ở các cột nền vàng.
A17: 4. Xem chỉ số | B17: Sheet 04 tính các tỷ lệ bằng công thức Excel từ sheet 02–03. Cột “Công thức” giải thích cách tính từng chỉ số, mục D–E là phần kiểm tra.
A18: 5. Tra cứu | B18: Sheet 05: danh mục 10-K, thuật ngữ, các số liệu còn thiếu và các lần NIKE trình bày lại số liệu.
A20: Quy ước trình bày
A21: Chữ xanh dương | B21: Số liệu nhập từ tài liệu nguồn (không phải công thức).
A22: Chữ xanh lá | B22: Công thức lấy số liệu từ sheet khác.
A23: Chữ đen | B23: Công thức tính toán.
A24: Số âm | B24: Trong ngoặc đơn, ví dụ (50), theo cách trình bày của NIKE. Tỷ lệ % dùng dấu trừ.
A25: Ô trống | B25: Đi kèm trạng thái “Thiếu / không công bố”, nghĩa là NIKE không công bố số liệu đó. Ô để trống chứ không điền số 0. Ở sheet 04, “–” nghĩa là không tính được vì thiếu số đầu vào.
A26: Tỷ lệ % | B26: Lưu dạng thập phân (0,14 hiển thị 14%) để dùng được trong công thức.
A27: Cột tiêu đề nền vàng | B27: Dành cho nhóm điền: người xác minh, ngày xác minh, ghi chú.
A29: Lưu ý khi dùng cho nghiên cứu
A30: Không suy ra nhân quả | B30: Các chỉ số chỉ cho thấy số liệu thay đổi trong cùng giai đoạn, không chứng minh việc thay đổi chiến lược kênh là nguyên nhân.
A31: Không có lợi nhuận theo kênh | B31: NIKE không công bố lợi nhuận hay chi phí riêng của NIKE Direct và bán buôn. SG&A là chi phí chung của cả công ty.
A32: Không trộn phạm vi | B32: Tỷ trọng các kênh tính trên doanh thu NIKE Brand, còn biên lợi nhuận tính trên doanh thu NIKE, Inc.
A33: Trích dẫn | B33: Khi dùng số liệu, trích dẫn 10-K gốc (năm, trang) thay vì trích dẫn file này.
A35: Liên kết dashboard | B35: https://miurikyasakytg2006-dot.github.io/nike-financial-dashboard/

Sheet 02 Dữ liệu tài chính
A1: Dữ liệu tài chính hợp nhất – NIKE, Inc.
A2: Báo cáo kết quả kinh doanh, hàng tồn kho, EBIT và tăng trưởng doanh thu NIKE công bố. Mỗi dòng là một chỉ tiêu của một năm tài chính.
A4: Năm tài chính | B4: Chỉ tiêu | C4: Giá trị | D4: Giá trị năm trước (cùng 10-K) | E4: Đơn vị | F4: Phạm vi báo cáo | G4: Kênh | H4: Loại số liệu | I4: Trạng thái dữ liệu | J4: Tài liệu nguồn (mở trên SEC) | K4: Trang | L4: Mục trong 10-K | M4: Vị trí chi tiết | N4: Số hoặc câu hiển thị trong tài liệu | O4: Đối chiếu tự động | P4: Trình bày lại ở 10-K sau | Q4: Người xác minh | R4: Ngày xác minh | S4: Ghi chú của nhóm | T4: Dòng trong 10-K (tiếng Anh) | U4: Thẻ XBRL | V4: Kỳ báo cáo | W4: Ngày nộp SEC | X4: Số accession | Y4: Mã chỉ tiêu | Z4: Mã quan sát
A5: FY2020 | B5: Doanh thu | C5: 37403 | D5: 39117 | E5: triệu USD | F5: NIKE, Inc. | G5: — | H5: GAAP – BCTC đã kiểm toán | I5: Khớp nguồn chính thức | J5: 10-K FY2020 | K5: 56 | L5: CONSOLIDATED STATEMENTS OF INCOME | M5: Item 8 – Consolidated Statements of Income, dòng “Revenues” | N5: 37,403 | O5: Khớp với dữ liệu XBRL do SEC công bố (cùng số accession). | P5: Không thay đổi khi trình bày lại trong 10-K FY2021, FY2022. | T5: Revenues | U5: us-gaap:RevenueFromContractWithCustomerExcludingAssessedTax | V5: 01/06/2019 – 31/05/2020 | W5: 24/07/2020 | X5: 0000320187-20-000047 | Y5: revenues | Z5: FY2020|revenues
A6: FY2021 | B6: Doanh thu | C6: 44538 | D6: 37403 | E6: triệu USD | F6: NIKE, Inc. | G6: — | H6: GAAP – BCTC đã kiểm toán | I6: Khớp nguồn chính thức | J6: 10-K FY2021 | K6: 57 | L6: CONSOLIDATED STATEMENTS OF INCOME | M6: Item 8 – Consolidated Statements of Income, dòng “Revenues” | N6: 44,538 | O6: Khớp với dữ liệu XBRL do SEC công bố (cùng số accession). | P6: Không thay đổi khi trình bày lại trong 10-K FY2022, FY2023. | T6: Revenues | U6: us-gaap:RevenueFromContractWithCustomerExcludingAssessedTax | V6: 01/06/2020 – 31/05/2021 | W6: 20/07/2021 | X6: 0000320187-21-000028 | Y6: revenues | Z6: FY2021|revenues
A7: FY2022 | B7: Doanh thu | C7: 46710 | D7: 44538 | E7: triệu USD | F7: NIKE, Inc. | G7: — | H7: GAAP – BCTC đã kiểm toán | I7: Khớp nguồn chính thức | J7: 10-K FY2022 | K7: 56 | L7: CONSOLIDATED STATEMENTS OF INCOME | M7: Item 8 – Consolidated Statements of Income, dòng “Revenues” | N7: 46,710 | O7: Khớp với dữ liệu XBRL do SEC công bố (cùng số accession). | P7: Không thay đổi khi trình bày lại trong 10-K FY2023, FY2024. | T7: Revenues | U7: us-gaap:RevenueFromContractWithCustomerExcludingAssessedTax | V7: 01/06/2021 – 31/05/2022 | W7: 21/07/2022 | X7: 0000320187-22-000038 | Y7: revenues | Z7: FY2022|revenues
A8: FY2023 | B8: Doanh thu | C8: 51217 | D8: 46710 | E8: triệu USD | F8: NIKE, Inc. | G8: — | H8: GAAP – BCTC đã kiểm toán | I8: Khớp nguồn chính thức | J8: 10-K FY2023 | K8: 55 | L8: CONSOLIDATED STATEMENTS OF INCOME | M8: Item 8 – Consolidated Statements of Income, dòng “Revenues” | N8: 51,217 | O8: Khớp với dữ liệu XBRL do SEC công bố (cùng số accession). | P8: Không thay đổi khi trình bày lại trong 10-K FY2024, FY2025. | T8: Revenues | U8: us-gaap:RevenueFromContractWithCustomerExcludingAssessedTax | V8: 01/06/2022 – 31/05/2023 | W8: 20/07/2023 | X8: 0000320187-23-000039 | Y8: revenues | Z8: FY2023|revenues
A9: FY2024 | B9: Doanh thu | C9: 51362 | D9: 51217 | E9: triệu USD | F9: NIKE, Inc. | G9: — | H9: GAAP – BCTC đã kiểm toán | I9: Khớp nguồn chính thức | J9: 10-K FY2024 | K9: 57 | L9: CONSOLIDATED STATEMENTS OF INCOME | M9: Item 8 – Consolidated Statements of Income, dòng “Revenues” | N9: 51,362 | O9: Khớp với dữ liệu XBRL do SEC công bố (cùng số accession). | P9: Không thay đổi khi trình bày lại trong 10-K FY2025, FY2026. | T9: Revenues | U9: us-gaap:RevenueFromContractWithCustomerExcludingAssessedTax | V9: 01/06/2023 – 31/05/2024 | W9: 25/07/2024 | X9: 0000320187-24-000044 | Y9: revenues | Z9: FY2024|revenues
A10: FY2025 | B10: Doanh thu | C10: 46309 | D10: 51362 | E10: triệu USD | F10: NIKE, Inc. | G10: — | H10: GAAP – BCTC đã kiểm toán | I10: Khớp nguồn chính thức | J10: 10-K FY2025 | K10: 56 | L10: CONSOLIDATED STATEMENTS OF INCOME | M10: Item 8 – Consolidated Statements of Income, dòng “Revenues” | N10: 46,309 | O10: Khớp với dữ liệu XBRL do SEC công bố (cùng số accession). | P10: Không thay đổi khi trình bày lại trong 10-K FY2026. | T10: Revenues | U10: us-gaap:RevenueFromContractWithCustomerExcludingAssessedTax | V10: 01/06/2024 – 31/05/2025 | W10: 17/07/2025 | X10: 0000320187-25-000047 | Y10: revenues | Z10: FY2025|revenues
A11: FY2026 | B11: Doanh thu | C11: 46398 | D11: 46309 | E11: triệu USD | F11: NIKE, Inc. | G11: — | H11: GAAP – BCTC đã kiểm toán | I11: Khớp nguồn chính thức | J11: 10-K FY2026 | K11: 55 | L11: CONSOLIDATED STATEMENTS OF INCOME | M11: Item 8 – Consolidated Statements of Income, dòng “Revenues” | N11: 46,398 | O11: Khớp với dữ liệu XBRL do SEC công bố (cùng số accession). | P11: Chưa có 10-K năm sau để so sánh. | T11: Revenues | U11: us-gaap:RevenueFromContractWithCustomerExcludingAssessedTax | V11: 01/06/2025 – 31/05/2026 | W11: 15/07/2026 | X11: 0000320187-26-000088 | Y11: revenues | Z11: FY2026|revenues
A12: FY2020 | B12: Giá vốn hàng bán | C12: 21162 | D12: 21643 | E12: triệu USD | F12: NIKE, Inc. | G12: — | H12: GAAP – BCTC đã kiểm toán | I12: Khớp nguồn chính thức | J12: 10-K FY2020 | K12: 56 | L12: CONSOLIDATED STATEMENTS OF INCOME | M12: Item 8 – Consolidated Statements of Income, dòng “Cost of sales” | N12: 21,162 | O12: Khớp với dữ liệu XBRL do SEC công bố (cùng số accession). | P12: Không thay đổi khi trình bày lại trong 10-K FY2021, FY2022. | T12: Cost of sales | U12: us-gaap:CostOfGoodsAndServicesSold | V12: 01/06/2019 – 31/05/2020 | W12: 24/07/2020 | X12: 0000320187-20-000047 | Y12: cost_of_sales | Z12: FY2020|cost_of_sales
A13: FY2021 | B13: Giá vốn hàng bán | C13: 24576 | D13: 21162 | E13: triệu USD | F13: NIKE, Inc. | G13: — | H13: GAAP – BCTC đã kiểm toán | I13: Khớp nguồn chính thức | J13: 10-K FY2021 | K13: 57 | L13: CONSOLIDATED STATEMENTS OF INCOME | M13: Item 8 – Consolidated Statements of Income, dòng “Cost of sales” | N13: 24,576 | O13: Khớp với dữ liệu XBRL do SEC công bố (cùng số accession). | P13: Không thay đổi khi trình bày lại trong 10-K FY2022, FY2023. | T13: Cost of sales | U13: us-gaap:CostOfGoodsAndServicesSold | V13: 01/06/2020 – 31/05/2021 | W13: 20/07/2021 | X13: 0000320187-21-000028 | Y13: cost_of_sales | Z13: FY2021|cost_of_sales
A14: FY2022 | B14: Giá vốn hàng bán | C14: 25231 | D14: 24576 | E14: triệu USD | F14: NIKE, Inc. | G14: — | H14: GAAP – BCTC đã kiểm toán | I14: Khớp nguồn chính thức | J14: 10-K FY2022 | K14: 56 | L14: CONSOLIDATED STATEMENTS OF INCOME | M14: Item 8 – Consolidated Statements of Income, dòng “Cost of sales” | N14: 25,231 | O14: Khớp với dữ liệu XBRL do SEC công bố (cùng số accession). | P14: Không thay đổi khi trình bày lại trong 10-K FY2023, FY2024. | T14: Cost of sales | U14: us-gaap:CostOfGoodsAndServicesSold | V14: 01/06/2021 – 31/05/2022 | W14: 21/07/2022 | X14: 0000320187-22-000038 | Y14: cost_of_sales | Z14: FY2022|cost_of_sales
A15: FY2023 | B15: Giá vốn hàng bán | C15: 28925 | D15: 25231 | E15: triệu USD | F15: NIKE, Inc. | G15: — | H15: GAAP – BCTC đã kiểm toán | I15: Khớp nguồn chính thức | J15: 10-K FY2023 | K15: 55 | L15: CONSOLIDATED STATEMENTS OF INCOME | M15: Item 8 – Consolidated Statements of Income, dòng “Cost of sales” | N15: 28,925 | O15: Khớp với dữ liệu XBRL do SEC công bố (cùng số accession). | P15: Không thay đổi khi trình bày lại trong 10-K FY2024, FY2025. | T15: Cost of sales | U15: us-gaap:CostOfGoodsAndServicesSold | V15: 01/06/2022 – 31/05/2023 | W15: 20/07/2023 | X15: 0000320187-23-000039 | Y15: cost_of_sales | Z15: FY2023|cost_of_sales
A16: FY2024 | B16: Giá vốn hàng bán | C16: 28475 | D16: 28925 | E16: triệu USD | F16: NIKE, Inc. | G16: — | H16: GAAP – BCTC đã kiểm toán | I16: Khớp nguồn chính thức | J16: 10-K FY2024 | K16: 57 | L16: CONSOLIDATED STATEMENTS OF INCOME | M16: Item 8 – Consolidated Statements of Income, dòng “Cost of sales” | N16: 28,475 | O16: Khớp với dữ liệu XBRL do SEC công bố (cùng số accession). | P16: Không thay đổi khi trình bày lại trong 10-K FY2025, FY2026. | T16: Cost of sales | U16: us-gaap:CostOfGoodsAndServicesSold | V16: 01/06/2023 – 31/05/2024 | W16: 25/07/2024 | X16: 0000320187-24-000044 | Y16: cost_of_sales | Z16: FY2024|cost_of_sales
... A95: FY2026 | B95: EBIT do NIKE công bố | C95: 3850 | D95: 3778 | E95: triệu USD | F95: NIKE, Inc. | G95: — | H95: Non-GAAP – NIKE định nghĩa | I95: Khớp nguồn chính thức | J95: 10-K FY2026 | K95: 36 | L95: ITEM 7 – MD&A | M95: Item 7 – MD&A, bảng “Total NIKE, Inc. EBIT” (mục Use of Non-GAAP Financial Measures / Operating Segments) | N95: TOTAL NIKE, INC. EBIT(1) | 3,850 | 3,778 | 2 | 6,539 | -42 | O95: Khớp với giá trị tự tính từ BCTC (chênh 0 triệu USD, ngưỡng ±1 triệu USD). | P95: Chưa có 10-K năm sau để so sánh. | T95: Total NIKE, Inc. Earnings Before Interest and Taxes (EBIT) | U95: Không gắn thẻ XBRL (MD&A) | V95: 01/06/2025 – 31/05/2026 | W95: 15/07/2026 | X95: 0000320187-26-000088 | Y95: ebit_reported | Z95: FY2026|ebit_reported
A96: FY2020 | B96: % thay đổi doanh thu (NIKE công bố, đã làm tròn) | C96: -0.04 | E96: % | F96: NIKE, Inc. | G96: — | H96: MD&A – % tính từ số GAAP | I96: Khớp nguồn chính thức | J96: 10-K FY2020 | K96: 31 | L96: ITEM 7 – MD&A | M96: Item 7 – MD&A, bảng doanh thu NIKE, Inc., cột “% CHANGE” | N96: TOTAL NIKE, INC. REVENUES | 37,403 | 39,117 | -4 | -2 | 36,397 | 7 | 11 | O96: Khớp với giá trị tự tính từ BCTC (chênh −0,38 điểm %, ngưỡng ±1 điểm %). | P96: Không áp dụng: tỷ lệ % chỉ lấy từ 10-K của chính năm đó. | T96: TOTAL NIKE, INC. REVENUES – % change | U96: Không gắn thẻ XBRL (MD&A) | V96: 01/06/2019 – 31/05/2020 | W96: 24/07/2020 | X96: 0000320187-20-000047 | Y96: revenues_pct_change_reported | Z96: FY2020|revenues_pct_change_reported
A97: FY2021 | B97: % thay đổi doanh thu (NIKE công bố, đã làm tròn) | C97: 0.19 | E97: % | F97: NIKE, Inc. | G97: — | H97: MD&A – % tính từ số GAAP | I97: Khớp nguồn chính thức | J97: 10-K FY2021 | K97: 32 | L97: ITEM 7 – MD&A | M97: Item 7 – MD&A, bảng doanh thu NIKE, Inc., cột “% CHANGE” | N97: TOTAL NIKE, INC. REVENUES | 44,538 | 37,403 | 19 | 17 | 39,117 | -4 | -2 | O97: Khớp với giá trị tự tính từ BCTC (chênh +0,08 điểm %, ngưỡng ±1 điểm %). | P97: Không áp dụng: tỷ lệ % chỉ lấy từ 10-K của chính năm đó. | T97: TOTAL NIKE, INC. REVENUES – % change | U97: Không gắn thẻ XBRL (MD&A) | V97: 01/06/2020 – 31/05/2021 | W97: 20/07/2021 | X97: 0000320187-21-000028 | Y97: revenues_pct_change_reported | Z97: FY2021|revenues_pct_change_reported
A98: FY2022 | B98: % thay đổi doanh thu (NIKE công bố, đã làm tròn) | C98: 0.05 | E98: % | F98: NIKE, Inc. | G98: — | H98: MD&A – % tính từ số GAAP | I98: Khớp nguồn chính thức | J98: 10-K FY2022 | K98: 32 | L98: ITEM 7 – MD&A | M98: Item 7 – MD&A, bảng doanh thu NIKE, Inc., cột “% CHANGE” | N98: TOTAL NIKE, INC. REVENUES | 46,710 | 44,538 | 5 | 6 | 37,403 | 19 | 17 | O98: Khớp với giá trị tự tính từ BCTC (chênh −0,12 điểm %, ngưỡng ±1 điểm %). | P98: Không áp dụng: tỷ lệ % chỉ lấy từ 10-K của chính năm đó. | T98: TOTAL NIKE, INC. REVENUES – % change | U98: Không gắn thẻ XBRL (MD&A) | V98: 01/06/2021 – 31/05/2022 | W98: 21/07/2022 | X98: 0000320187-22-000038 | Y98: revenues_pct_change_reported | Z98: FY2022|revenues_pct_change_reported
A99: FY2023 | B99: % thay đổi doanh thu (NIKE công bố, đã làm tròn) | C99: 0.1 | E99: % | F99: NIKE, Inc. | G99: — | H99: MD&A – % tính từ số GAAP | I99: Khớp nguồn chính thức | J99: 10-K FY2023 | K99: 32 | L99: ITEM 7 – MD&A | M99: Item 7 – MD&A, bảng doanh thu NIKE, Inc., cột “% CHANGE” | N99: TOTAL NIKE, INC. REVENUES | 51,217 | 46,710 | 10 | 16 | 44,538 | 5 | 6 | O99: Khớp với giá trị tự tính từ BCTC (chênh −0,35 điểm %, ngưỡng ±1 điểm %). | P99: Không áp dụng: tỷ lệ % chỉ lấy từ 10-K của chính năm đó. | T99: TOTAL NIKE, INC. REVENUES – % change | U99: Không gắn thẻ XBRL (MD&A) | V99: 01/06/2022 – 31/05/2023 | W99: 20/07/2023 | X99: 0000320187-23-000039 | Y99: revenues_pct_change_reported | Z99: FY2023|revenues_pct_change_reported
A100: FY2024 | B100: % thay đổi doanh thu (NIKE công bố, đã làm tròn) | C100: 0 | E100: % | F100: NIKE, Inc. | G100: — | H100: MD&A – % tính từ số GAAP | I100: Khớp nguồn chính thức | J100: 10-K FY2024 | K100: 34 | L100: ITEM 7 – MD&A | M100: Item 7 – MD&A, bảng doanh thu NIKE, Inc., cột “% CHANGE” | N100: TOTAL NIKE, INC. REVENUES | 51,362 | 51,217 | 0 | 1 | 46,710 | 10 | 16 | O100: Khớp với giá trị tự tính từ BCTC (chênh +0,28 điểm %, ngưỡng ±1 điểm %). | P100: Không áp dụng: tỷ lệ % chỉ lấy từ 10-K của chính năm đó. | T100: TOTAL NIKE, INC. REVENUES – % change | U100: Không gắn thẻ XBRL (MD&A) | V100: 01/06/2023 – 31/05/2024 | W100: 25/07/2024 | X100: 0000320187-24-000044 | Y100: revenues_pct_change_reported | Z100: FY2024|revenues_pct_change_reported
A101: FY2025 | B101: % thay đổi doanh thu (NIKE công bố, đã làm tròn) | C101: -0.1 | E101: % | F101: NIKE, Inc. | G101: — | H101: MD&A – % tính từ số GAAP | I101: Khớp nguồn chính thức | J101: 10-K FY2025 | K101: 33 | L101: ITEM 7 – MD&A | M101: Item 7 – MD&A, bảng doanh thu NIKE, Inc., cột “% CHANGE” | N101: TOTAL NIKE, INC. REVENUES | 46,309 | 51,362 | -10 | -9 | 51,217 | 0 | 1 | O101: Khớp với giá trị tự tính từ BCTC (chênh +0,16 điểm %, ngưỡng ±1 điểm %). | P101: Không áp dụng: tỷ lệ % chỉ lấy từ 10-K của chính năm đó. | T101: TOTAL NIKE, INC. REVENUES – % change | U101: Không gắn thẻ XBRL (MD&A) | V101: 01/06/2024 – 31/05/2025 | W101: 17/07/2025 | X101: 0000320187-25-000047 | Y101: revenues_pct_change_reported | Z101: FY2025|revenues_pct_change_reported
A102: FY2026 | B102: % thay đổi doanh thu (NIKE công bố, đã làm tròn) | C102: 0 | E102: % | F102: NIKE, Inc. | G102: — | H102: MD&A – % tính từ số GAAP | I102: Khớp nguồn chính thức | J102: 10-K FY2026 | K102: 32 | L102: ITEM 7 – MD&A | M102: Item 7 – MD&A, bảng doanh thu NIKE, Inc., cột “% CHANGE” | N102: TOTAL NIKE, INC. REVENUES | 46,398 | 46,309 | 0 | -2 | 51,362 | -10 | -9 | O102: Khớp với giá trị tự tính từ BCTC (chênh +0,19 điểm %, ngưỡng ±1 điểm %). | P102: Không áp dụng: tỷ lệ % chỉ lấy từ 10-K của chính năm đó. | T102: TOTAL NIKE, INC. REVENUES – % change | U102: Không gắn thẻ XBRL (MD&A) | V102: 01/06/2025 – 31/05/2026 | W102: 15/07/2026 | X102: 0000320187-26-000088 | Y102: revenues_pct_change_reported | Z102: FY2026|revenues_pct_change_reported
A103: FY2020 | B103: % thay đổi doanh thu loại trừ tỷ giá | C103: -0.02 | E103: % | F103: NIKE, Inc. | G103: — | H103: Non-GAAP – NIKE định nghĩa | I103: Khớp nguồn chính thức | J103: 10-K FY2020 | K103: 31 | L103: ITEM 7 – MD&A | M103: Item 7 – MD&A, bảng doanh thu NIKE, Inc., cột “% CHANGE EXCLUDING CURRENCY CHANGES” | N103: TOTAL NIKE, INC. REVENUES | 37,403 | 39,117 | -4 | -2 | 36,397 | 7 | 11 | O103: Đã đọc lại ngay trên trang 10-K (tr. 31): khớp. Ảnh chụp đối chiếu: handover/bang-chung-doi-chieu/FY2020-bang-doanh-thu-tr31.png. | P103: Không áp dụng: tỷ lệ % chỉ lấy từ 10-K của chính năm đó. | T103: TOTAL NIKE, INC. REVENUES – % change excluding currency changes | U103: Không gắn thẻ XBRL (MD&A) | V103: 01/06/2019 – 31/05/2020 | W103: 24/07/2020 | X103: 0000320187-20-000047 | Y103: revenues_pct_change_cn | Z103: FY2020|revenues_pct_change_cn
A104: FY2021 | B104: % thay đổi doanh thu loại trừ tỷ giá | C104: 0.17 | E104: % | F104: NIKE, Inc. | G104: — | H104: Non-GAAP – NIKE định nghĩa | I104: Khớp nguồn chính thức | J104: 10-K FY2021 | K104: 32 | L104: ITEM 7 – MD&A | M104: Item 7 – MD&A, bảng doanh thu NIKE, Inc., cột “% CHANGE EXCLUDING CURRENCY CHANGES” | N104: TOTAL NIKE, INC. REVENUES | 44,538 | 37,403 | 19 | 17 | 39,117 | -4 | -2 | O104: Đã đọc lại ngay trên trang 10-K (tr. 32): khớp. Ảnh chụp đối chiếu: handover/bang-chung-doi-chieu/FY2021-bang-doanh-thu-tr32.png. | P104: Không áp dụng: tỷ lệ % chỉ lấy từ 10-K của chính năm đó. | T104: TOTAL NIKE, INC. REVENUES – % change excluding currency changes | U104: Không gắn thẻ XBRL (MD&A) | V104: 01/06/2020 – 31/05/2021 | W104: 20/07/2021 | X104: 0000320187-21-000028 | Y104: revenues_pct_change_cn | Z104: FY2021|revenues_pct_change_cn
A105: FY2022 | B105: % thay đổi doanh thu loại trừ tỷ giá | C105: 0.06 | E105: % | F105: NIKE, Inc. | G105: — | H105: Non-GAAP – NIKE định nghĩa | I105: Khớp nguồn chính thức | J105: 10-K FY2022 | K105: 32 | L105: ITEM 7 – MD&A | M105: Item 7 – MD&A, bảng doanh thu NIKE, Inc., cột “% CHANGE EXCLUDING CURRENCY CHANGES” | N105: TOTAL NIKE, INC. REVENUES | 46,710 | 44,538 | 5 | 6 | 37,403 | 19 | 17 | O105: Đã đọc lại ngay trên trang 10-K (tr. 32): khớp. Ảnh chụp đối chiếu: handover/bang-chung-doi-chieu/FY2022-bang-doanh-thu-tr32.png. | P105: Không áp dụng: tỷ lệ % chỉ lấy từ 10-K của chính năm đó. | T105: TOTAL NIKE, INC. REVENUES – % change excluding currency changes | U105: Không gắn thẻ XBRL (MD&A) | V105: 01/06/2021 – 31/05/2022 | W105: 21/07/2022 | X105: 0000320187-22-000038 | Y105: revenues_pct_change_cn | Z105: FY2022|revenues_pct_change_cn
A106: FY2023 | B106: % thay đổi doanh thu loại trừ tỷ giá | C106: 0.16 | E106: % | F106: NIKE, Inc. | G106: — | H106: Non-GAAP – NIKE định nghĩa | I106: Khớp nguồn chính thức | J106: 10-K FY2023 | K106: 32 | L106: ITEM 7 – MD&A | M106: Item 7 – MD&A, bảng doanh thu NIKE, Inc., cột “% CHANGE EXCLUDING CURRENCY CHANGES” | N106: TOTAL NIKE, INC. REVENUES | 51,217 | 46,710 | 10 | 16 | 44,538 | 5 | 6 | O106: Đã đọc lại ngay trên trang 10-K (tr. 32): khớp. Ảnh chụp đối chiếu: handover/bang-chung-doi-chieu/FY2023-bang-doanh-thu-tr32.png. | P106: Không áp dụng: tỷ lệ % chỉ lấy từ 10-K của chính năm đó. | T106: TOTAL NIKE, INC. REVENUES – % change excluding currency changes | U106: Không gắn thẻ XBRL (MD&A) | V106: 01/06/2022 – 31/05/2023 | W106: 20/07/2023 | X106: 0000320187-23-000039 | Y106: revenues_pct_change_cn | Z106: FY2023|revenues_pct_change_cn
A107: FY2024 | B107: % thay đổi doanh thu loại trừ tỷ giá | C107: 0.01 | E107: % | F107: NIKE, Inc. | G107: — | H107: Non-GAAP – NIKE định nghĩa | I107: Khớp nguồn chính thức | J107: 10-K FY2024 | K107: 34 | L107: ITEM 7 – MD&A | M107: Item 7 – MD&A, bảng doanh thu NIKE, Inc., cột “% CHANGE EXCLUDING CURRENCY CHANGES” | N107: TOTAL NIKE, INC. REVENUES | 51,362 | 51,217 | 0 | 1 | 46,710 | 10 | 16 | O107: Đã đọc lại ngay trên trang 10-K (tr. 34): khớp. Ảnh chụp đối chiếu: handover/bang-chung-doi-chieu/FY2024-bang-doanh-thu-tr34.png. | P107: Không áp dụng: tỷ lệ % chỉ lấy từ 10-K của chính năm đó. | T107: TOTAL NIKE, INC. REVENUES – % change excluding currency changes | U107: Không gắn thẻ XBRL (MD&A) | V107: 01/06/2023 – 31/05/2024 | W107: 25/07/2024 | X107: 0000320187-24-000044 | Y107: revenues_pct_change_cn | Z107: FY2024|revenues_pct_change_cn
... A109: FY2026 | B109: % thay đổi doanh thu loại trừ tỷ giá | C109: -0.02 | E109: % | F109: NIKE, Inc. | G109: — | H109: Non-GAAP – NIKE định nghĩa | I109: Khớp nguồn chính thức | J109: 10-K FY2026 | K109: 32 | L109: ITEM 7 – MD&A | M109: Item 7 – MD&A, bảng doanh thu NIKE, Inc., cột “% CHANGE EXCLUDING CURRENCY CHANGES” | N109: TOTAL NIKE, INC. REVENUES | 46,398 | 46,309 | 0 | -2 | 51,362 | -10 | -9 | O109: Đã đọc lại ngay trên trang 10-K (tr. 32): khớp. Ảnh chụp đối chiếu: handover/bang-chung-doi-chieu/FY2026-bang-doanh-thu-tr32.png. | P109: Không áp dụng: tỷ lệ % chỉ lấy từ 10-K của chính năm đó. | T109: TOTAL NIKE, INC. REVENUES – % change excluding currency changes | U109: Không gắn thẻ XBRL (MD&A) | V109: 01/06/2025 – 31/05/2026 | W109: 15/07/2026 | X109: 0000320187-26-000088 | Y109: revenues_pct_change_cn | Z109: FY2026|revenues_pct_change_cn

Sheet 03 Kênh phân phối
A1: Kênh phân phối – NIKE Brand
A2: Doanh thu NIKE Direct, bán buôn, Global Brand Divisions, doanh số Digital và tăng trưởng theo kênh NIKE công bố. Converse và Corporate chỉ để đối chiếu.
A4: Năm tài chính | B4: Chỉ tiêu | C4: Giá trị | D4: Giá trị năm trước (cùng 10-K) | E4: Đơn vị | F4: Phạm vi báo cáo | G4: Kênh | H4: Loại số liệu | I4: Trạng thái dữ liệu | J4: Tài liệu nguồn (mở trên SEC) | K4: Trang | L4: Mục trong 10-K | M4: Vị trí chi tiết | N4: Số hoặc câu hiển thị trong tài liệu | O4: Đối chiếu tự động | P4: Trình bày lại ở 10-K sau | Q4: Người xác minh | R4: Ngày xác minh | S4: Ghi chú của nhóm | T4: Dòng trong 10-K (tiếng Anh) | U4: Thẻ XBRL | V4: Kỳ báo cáo | W4: Ngày nộp SEC | X4: Số accession | Y4: Mã chỉ tiêu | Z4: Mã quan sát
A5: FY2020 | B5: Doanh thu NIKE Direct | C5: 12382 | D5: 11753 | E5: triệu USD | F5: NIKE Brand | G5: NIKE Direct | H5: GAAP – BCTC đã kiểm toán | I5: Khớp nguồn chính thức | J5: 10-K FY2020 | K5: 88 | L5: NOTE 16 — REVENUES | M5: Item 8 – Note “Revenues”, bảng phân tách doanh thu, cột “Total NIKE Brand”, dòng “Sales through Direct to Consumer” | N5: 12,382 | O5: Khớp bảng doanh thu trong MD&A (trang 31). | P5: Không thay đổi khi trình bày lại trong 10-K FY2021, FY2022. | T5: Sales through Direct to Consumer (NIKE Brand) | U5: us-gaap:RevenueFromContractWithCustomerExcludingAssessedTax [ConsolidationItemsAxis=OperatingSegmentsMember; ContractWithCustomerSalesChannelAxis=SalesChannelDirectlyToConsumerMember; StatementBusinessSegmentsAxis=NIKEBrandMember] | V5: 01/06/2019 – 31/05/2020 | W5: 24/07/2020 | X5: 0000320187-20-000047 | Y5: nike_direct_revenue | Z5: FY2020|nike_direct_revenue
A6: FY2021 | B6: Doanh thu NIKE Direct | C6: 16370 | D6: 12382 | E6: triệu USD | F6: NIKE Brand | G6: NIKE Direct | H6: GAAP – BCTC đã kiểm toán | I6: Khớp nguồn chính thức | J6: 10-K FY2021 | K6: 86 | L6: NOTE 16 — REVENUES | M6: Item 8 – Note “Revenues”, bảng phân tách doanh thu, cột “Total NIKE Brand”, dòng “Sales through Direct to Consumer” | N6: 16,370 | O6: Khớp bảng doanh thu trong MD&A (trang 32). | P6: Không thay đổi khi trình bày lại trong 10-K FY2022, FY2023. | T6: Sales through Direct to Consumer (NIKE Brand) | U6: us-gaap:RevenueFromContractWithCustomerExcludingAssessedTax [ConsolidationItemsAxis=OperatingSegmentsMember; ContractWithCustomerSalesChannelAxis=SalesChannelDirectlyToConsumerMember; StatementBusinessSegmentsAxis=NIKEBrandMember] | V6: 01/06/2020 – 31/05/2021 | W6: 20/07/2021 | X6: 0000320187-21-000028 | Y6: nike_direct_revenue | Z6: FY2021|nike_direct_revenue
A7: FY2022 | B7: Doanh thu NIKE Direct | C7: 18726 | D7: 16370 | E7: triệu USD | F7: NIKE Brand | G7: NIKE Direct | H7: GAAP – BCTC đã kiểm toán | I7: Khớp nguồn chính thức | J7: 10-K FY2022 | K7: 85 | L7: NOTE 16 — REVENUES | M7: Item 8 – Note “Revenues”, bảng phân tách doanh thu, cột “Total NIKE Brand”, dòng “Sales through Direct to Consumer” | N7: 18,726 | O7: Khớp bảng doanh thu trong MD&A (trang 32). | P7: Không thay đổi khi trình bày lại trong 10-K FY2023, FY2024. | T7: Sales through Direct to Consumer (NIKE Brand) | U7: us-gaap:RevenueFromContractWithCustomerExcludingAssessedTax [ConsolidationItemsAxis=OperatingSegmentsMember; ContractWithCustomerSalesChannelAxis=SalesChannelDirectlyToConsumerMember; StatementBusinessSegmentsAxis=NIKEBrandMember] | V7: 01/06/2021 – 31/05/2022 | W7: 21/07/2022 | X7: 0000320187-22-000038 | Y7: nike_direct_revenue | Z7: FY2022|nike_direct_revenue
A8: FY2023 | B8: Doanh thu NIKE Direct | C8: 21308 | D8: 18726 | E8: triệu USD | F8: NIKE Brand | G8: NIKE Direct | H8: GAAP – BCTC đã kiểm toán | I8: Khớp nguồn chính thức | J8: 10-K FY2023 | K8: 83 | L8: NOTE 14 — REVENUES | M8: Item 8 – Note “Revenues”, bảng phân tách doanh thu, cột “Total NIKE Brand”, dòng “Sales through Direct to Consumer” | N8: 21,308 | O8: Khớp bảng doanh thu trong MD&A (trang 32). | P8: Không thay đổi khi trình bày lại trong 10-K FY2024, FY2025. | T8: Sales through Direct to Consumer (NIKE Brand) | U8: us-gaap:RevenueFromContractWithCustomerExcludingAssessedTax [ConsolidationItemsAxis=OperatingSegmentsMember; ContractWithCustomerSalesChannelAxis=SalesChannelDirectlyToConsumerMember; StatementBusinessSegmentsAxis=NIKEBrandMember] | V8: 01/06/2022 – 31/05/2023 | W8: 20/07/2023 | X8: 0000320187-23-000039 | Y8: nike_direct_revenue | Z8: FY2023|nike_direct_revenue
A9: FY2024 | B9: Doanh thu NIKE Direct | C9: 21519 | D9: 21308 | E9: triệu USD | F9: NIKE Brand | G9: NIKE Direct | H9: GAAP – BCTC đã kiểm toán | I9: Khớp nguồn chính thức | J9: 10-K FY2024 | K9: 84 | L9: NOTE 14 — REVENUES | M9: Item 8 – Note “Revenues”, bảng phân tách doanh thu, cột “Total NIKE Brand”, dòng “Sales through Direct to Consumer” | N9: 21,519 | O9: Khớp bảng doanh thu trong MD&A (trang 34). | P9: Không thay đổi khi trình bày lại trong 10-K FY2025, FY2026. | T9: Sales through Direct to Consumer (NIKE Brand) | U9: us-gaap:RevenueFromContractWithCustomerExcludingAssessedTax [ConsolidationItemsAxis=OperatingSegmentsMember; ContractWithCustomerSalesChannelAxis=SalesChannelDirectlyToConsumerMember; StatementBusinessSegmentsAxis=NIKEBrandMember] | V9: 01/06/2023 – 31/05/2024 | W9: 25/07/2024 | X9: 0000320187-24-000044 | Y9: nike_direct_revenue | Z9: FY2024|nike_direct_revenue
A10: FY2025 | B10: Doanh thu NIKE Direct | C10: 18783 | D10: 21519 | E10: triệu USD | F10: NIKE Brand | G10: NIKE Direct | H10: GAAP – BCTC đã kiểm toán | I10: Khớp nguồn chính thức | J10: 10-K FY2025 | K10: 82 | L10: NOTE 14 — REVENUES | M10: Item 8 – Note “Revenues”, bảng phân tách doanh thu, cột “Total NIKE Brand”, dòng “Sales through Direct to Consumer” | N10: 18,783 | O10: Khớp bảng doanh thu trong MD&A (trang 33). | P10: Không thay đổi khi trình bày lại trong 10-K FY2026. | T10: Sales through Direct to Consumer (NIKE Brand) | U10: us-gaap:RevenueFromContractWithCustomerExcludingAssessedTax [ConsolidationItemsAxis=OperatingSegmentsMember; ContractWithCustomerSalesChannelAxis=SalesChannelDirectlyToConsumerMember; StatementBusinessSegmentsAxis=NIKEBrandMember] | V10: 01/06/2024 – 31/05/2025 | W10: 17/07/2025 | X10: 0000320187-25-000047 | Y10: nike_direct_revenue | Z10: FY2025|nike_direct_revenue
A11: FY2026 | B11: Doanh thu NIKE Direct | C11: 17720 | D11: 18783 | E11: triệu USD | F11: NIKE Brand | G11: NIKE Direct | H11: GAAP – BCTC đã kiểm toán | I11: Khớp nguồn chính thức | J11: 10-K FY2026 | K11: 83 | L11: NOTE 14 — REVENUES | M11: Item 8 – Note “Revenues”, bảng phân tách doanh thu, cột “Total NIKE Brand”, dòng “Sales through Direct to Consumer” | N11: 17,720 | O11: Khớp bảng doanh thu trong MD&A (trang 32). | P11: Chưa có 10-K năm sau để so sánh. | T11: Sales through Direct to Consumer (NIKE Brand) | U11: us-gaap:RevenueFromContractWithCustomerExcludingAssessedTax [ConsolidationItemsAxis=OperatingSegmentsMember; ContractWithCustomerSalesChannelAxis=SalesChannelDirectlyToConsumerMember; StatementBusinessSegmentsAxis=NIKEBrandMember] | V11: 01/06/2025 – 31/05/2026 | W11: 15/07/2026 | X11: 0000320187-26-000088 | Y11: nike_direct_revenue | Z11: FY2026|nike_direct_revenue
A12: FY2020 | B12: Doanh thu bán buôn NIKE Brand | C12: 23156 | D12: 25423 | E12: triệu USD | F12: NIKE Brand | G12: Bán buôn (Wholesale) | H12: GAAP – BCTC đã kiểm toán | I12: Khớp nguồn chính thức | J12: 10-K FY2020 | K12: 88 | L12: NOTE 16 — REVENUES | M12: Item 8 – Note “Revenues”, bảng phân tách doanh thu, cột “Total NIKE Brand”, dòng “Sales to Wholesale Customers” | N12: 23,156 | O12: Khớp bảng doanh thu trong MD&A (trang 31). | P12: Không thay đổi khi trình bày lại trong 10-K FY2021, FY2022. | T12: Sales to Wholesale Customers (NIKE Brand) | U12: us-gaap:RevenueFromContractWithCustomerExcludingAssessedTax [ConsolidationItemsAxis=OperatingSegmentsMember; ContractWithCustomerSalesChannelAxis=SalesChannelWholesaleMember; StatementBusinessSegmentsAxis=NIKEBrandMember] | V12: 01/06/2019 – 31/05/2020 | W12: 24/07/2020 | X12: 0000320187-20-000047 | Y12: nike_brand_wholesale_revenue | Z12: FY2020|nike_brand_wholesale_revenue
A13: FY2021 | B13: Doanh thu bán buôn NIKE Brand | C13: 25898 | D13: 23156 | E13: triệu USD | F13: NIKE Brand | G13: Bán buôn (Wholesale) | H13: GAAP – BCTC đã kiểm toán | I13: Khớp nguồn chính thức | J13: 10-K FY2021 | K13: 86 | L13: NOTE 16 — REVENUES | M13: Item 8 – Note “Revenues”, bảng phân tách doanh thu, cột “Total NIKE Brand”, dòng “Sales to Wholesale Customers” | N13: 25,898 | O13: Khớp bảng doanh thu trong MD&A (trang 32). | P13: Không thay đổi khi trình bày lại trong 10-K FY2022, FY2023. | T13: Sales to Wholesale Customers (NIKE Brand) | U13: us-gaap:RevenueFromContractWithCustomerExcludingAssessedTax [ConsolidationItemsAxis=OperatingSegmentsMember; ContractWithCustomerSalesChannelAxis=SalesChannelWholesaleMember; StatementBusinessSegmentsAxis=NIKEBrandMember] | V13: 01/06/2020 – 31/05/2021 | W13: 20/07/2021 | X13: 0000320187-21-000028 | Y13: nike_brand_wholesale_revenue | Z13: FY2021|nike_brand_wholesale_revenue
A14: FY2022 | B14: Doanh thu bán buôn NIKE Brand | C14: 25608 | D14: 25898 | E14: triệu USD | F14: NIKE Brand | G14: Bán buôn (Wholesale) | H14: GAAP – BCTC đã kiểm toán | I14: Khớp nguồn chính thức | J14: 10-K FY2022 | K14: 85 | L14: NOTE 16 — REVENUES | M14: Item 8 – Note “Revenues”, bảng phân tách doanh thu, cột “Total NIKE Brand”, dòng “Sales to Wholesale Customers” | N14: 25,608 | O14: Khớp bảng doanh thu trong MD&A (trang 32). | P14: Không thay đổi khi trình bày lại trong 10-K FY2023, FY2024. | T14: Sales to Wholesale Customers (NIKE Brand) | U14: us-gaap:RevenueFromContractWithCustomerExcludingAssessedTax [ConsolidationItemsAxis=OperatingSegmentsMember; ContractWithCustomerSalesChannelAxis=SalesChannelWholesaleMember; StatementBusinessSegmentsAxis=NIKEBrandMember] | V14: 01/06/2021 – 31/05/2022 | W14: 21/07/2022 | X14: 0000320187-22-000038 | Y14: nike_brand_wholesale_revenue | Z14: FY2022|nike_brand_wholesale_revenue
A15: FY2023 | B15: Doanh thu bán buôn NIKE Brand | C15: 27397 | D15: 25608 | E15: triệu USD | F15: NIKE Brand | G15: Bán buôn (Wholesale) | H15: GAAP – BCTC đã kiểm toán | I15: Khớp nguồn chính thức | J15: 10-K FY2023 | K15: 83 | L15: NOTE 14 — REVENUES | M15: Item 8 – Note “Revenues”, bảng phân tách doanh thu, cột “Total NIKE Brand”, dòng “Sales to Wholesale Customers” | N15: 27,397 | O15: Khớp bảng doanh thu trong MD&A (trang 32). | P15: Không thay đổi khi trình bày lại trong 10-K FY2024, FY2025. | T15: Sales to Wholesale Customers (NIKE Brand) | U15: us-gaap:RevenueFromContractWithCustomerExcludingAssessedTax [ConsolidationItemsAxis=OperatingSegmentsMember; ContractWithCustomerSalesChannelAxis=SalesChannelWholesaleMember; StatementBusinessSegmentsAxis=NIKEBrandMember] | V15: 01/06/2022 – 31/05/2023 | W15: 20/07/2023 | X15: 0000320187-23-000039 | Y15: nike_brand_wholesale_revenue | Z15: FY2023|nike_brand_wholesale_revenue
A16: FY2024 | B16: Doanh thu bán buôn NIKE Brand | C16: 27758 | D16: 27397 | E16: triệu USD | F16: NIKE Brand | G16: Bán buôn (Wholesale) | H16: GAAP – BCTC đã kiểm toán | I16: Khớp nguồn chính thức | J16: 10-K FY2024 | K16: 84 | L16: NOTE 14 — REVENUES | M16: Item 8 – Note “Revenues”, bảng phân tách doanh thu, cột “Total NIKE Brand”, dòng “Sales to Wholesale Customers” | N16: 27,758 | O16: Khớp bảng doanh thu trong MD&A (trang 34). | P16: Không thay đổi khi trình bày lại trong 10-K FY2025, FY2026. | T16: Sales to Wholesale Customers (NIKE Brand) | U16: us-gaap:RevenueFromContractWithCustomerExcludingAssessedTax [ConsolidationItemsAxis=OperatingSegmentsMember; ContractWithCustomerSalesChannelAxis=SalesChannelWholesaleMember; StatementBusinessSegmentsAxis=NIKEBrandMember] | V16: 01/06/2023 – 31/05/2024 | W16: 25/07/2024 | X16: 0000320187-24-000044 | Y16: nike_brand_wholesale_revenue | Z16: FY2024|nike_brand_wholesale_revenue
... A53: FY2026 | B53: Doanh số NIKE Brand Digital | C53: 8.6 | D53: 9.6 | E53: tỷ USD | F53: NIKE Brand | G53: NIKE Direct – Digital | H53: MD&A – ban điều hành nêu, không kiểm toán | I53: Khớp nguồn chính thức | J53: 10-K FY2026 | K53: 33 | L53: ITEM 7 – MD&A | M53: Item 7 – MD&A, đoạn văn về NIKE Direct (câu trích ở cột “Số hoặc câu hiển thị trong tài liệu”) | N53: NIKE Brand Digital sales were $8.6 billion in fiscal 2026 compared to $9.6 billion in fiscal 2025, with declines primarily due to reduced traffic. | O53: Đã đọc lại ngay trên trang 10-K (tr. 33): khớp. Ảnh chụp đối chiếu: handover/bang-chung-doi-chieu/FY2026-digital-tr33.png. | P53: Chưa có 10-K năm sau để so sánh. | T53: NIKE Brand Digital sales (FY2020–21: “Digital commerce sales”) | U53: Không gắn thẻ XBRL (MD&A) | V53: 01/06/2025 – 31/05/2026 | W53: 15/07/2026 | X53: 0000320187-26-000088 | Y53: nike_brand_digital_sales | Z53: FY2026|nike_brand_digital_sales
A54: FY2020 | B54: Tỷ trọng NIKE Direct do NIKE nêu (xấp xỉ) | C54: 0.35 | E54: % | F54: NIKE Brand | G54: NIKE Direct | H54: MD&A – ban điều hành nêu, không kiểm toán | I54: Khớp nguồn chính thức | J54: 10-K FY2020 | K54: 32 | L54: ITEM 7 – MD&A | M54: Item 7 – MD&A, câu “NIKE Direct revenues represented approximately …% of total NIKE Brand revenues” | N54: On a reported basis, NIKE Direct revenues represented approximately 35% of our total NIKE Brand revenues for fiscal 2020, compared to 32% for fiscal 2019. | O54: Khớp với giá trị tự tính từ BCTC (chênh −0,19 điểm %, ngưỡng ±1 điểm %). | P54: Không thay đổi khi trình bày lại trong 10-K FY2021. | T54: NIKE Direct as approx. % of total NIKE Brand revenues (as stated) | U54: Không gắn thẻ XBRL (MD&A) | V54: 01/06/2019 – 31/05/2020 | W54: 24/07/2020 | X54: 0000320187-20-000047 | Y54: nike_direct_share_stated | Z54: FY2020|nike_direct_share_stated
A55: FY2021 | B55: Tỷ trọng NIKE Direct do NIKE nêu (xấp xỉ) | C55: 0.39 | E55: % | F55: NIKE Brand | G55: NIKE Direct | H55: MD&A – ban điều hành nêu, không kiểm toán | I55: Khớp nguồn chính thức | J55: 10-K FY2021 | K55: 33 | L55: ITEM 7 – MD&A | M55: Item 7 – MD&A, câu “NIKE Direct revenues represented approximately …% of total NIKE Brand revenues” | N55: On a reported basis, NIKE Direct revenues represented approximately 39% of our total NIKE Brand revenues for fiscal 2021 compared to 35% for fiscal 2020. | O55: Khớp với giá trị tự tính từ BCTC (chênh −0,29 điểm %, ngưỡng ±1 điểm %). | P55: Không thay đổi khi trình bày lại trong 10-K FY2022. | T55: NIKE Direct as approx. % of total NIKE Brand revenues (as stated) | U55: Không gắn thẻ XBRL (MD&A) | V55: 01/06/2020 – 31/05/2021 | W55: 20/07/2021 | X55: 0000320187-21-000028 | Y55: nike_direct_share_stated | Z55: FY2021|nike_direct_share_stated
A56: FY2022 | B56: Tỷ trọng NIKE Direct do NIKE nêu (xấp xỉ) | C56: 0.42 | E56: % | F56: NIKE Brand | G56: NIKE Direct | H56: MD&A – ban điều hành nêu, không kiểm toán | I56: Khớp nguồn chính thức | J56: 10-K FY2022 | K56: 28 | L56: ITEM 7 – MD&A | M56: Item 7 – MD&A, câu “NIKE Direct revenues represented approximately …% of total NIKE Brand revenues” | N56: Over the last several years, as we have executed against the Consumer Direct Acceleration, we have grown our NIKE Direct business to be approximately 42% of total NIKE Brand revenues for fiscal 2022, and we have reduced the number of wholesale accounts globally. | O56: Khớp với giá trị tự tính từ BCTC (chênh +0,14 điểm %, ngưỡng ±1 điểm %). | P56: 10-K năm sau không trình bày lại số này. | T56: NIKE Direct as approx. % of total NIKE Brand revenues (as stated) | U56: Không gắn thẻ XBRL (MD&A) | V56: 01/06/2021 – 31/05/2022 | W56: 21/07/2022 | X56: 0000320187-22-000038 | Y56: nike_direct_share_stated | Z56: FY2022|nike_direct_share_stated
A57: FY2023 | B57: Tỷ trọng NIKE Direct do NIKE nêu (xấp xỉ) | C57: 0.44 | E57: % | F57: NIKE Brand | G57: NIKE Direct | H57: MD&A – ban điều hành nêu, không kiểm toán | I57: Khớp nguồn chính thức | J57: 10-K FY2023 | K57: 28 | L57: ITEM 7 – MD&A | M57: Item 7 – MD&A, câu “NIKE Direct revenues represented approximately …% of total NIKE Brand revenues” | N57: NIKE Direct revenues grew 14% from $18.7 billion in fiscal 2022 to $21.3 billion in fiscal 2023, and represented approximately 44% of total NIKE Brand revenues for fiscal 2023 | O57: Khớp với giá trị tự tính từ BCTC (chênh −0,30 điểm %, ngưỡng ±1 điểm %). | P57: 10-K năm sau không trình bày lại số này. | T57: NIKE Direct as approx. % of total NIKE Brand revenues (as stated) | U57: Không gắn thẻ XBRL (MD&A) | V57: 01/06/2022 – 31/05/2023 | W57: 20/07/2023 | X57: 0000320187-23-000039 | Y57: nike_direct_share_stated | Z57: FY2023|nike_direct_share_stated
A58: FY2024 | B58: Tỷ trọng NIKE Direct do NIKE nêu (xấp xỉ) | C58: 0.44 | E58: % | F58: NIKE Brand | G58: NIKE Direct | H58: MD&A – ban điều hành nêu, không kiểm toán | I58: Khớp nguồn chính thức | J58: 10-K FY2024 | K58: 30 | L58: ITEM 7 – MD&A | M58: Item 7 – MD&A, câu “NIKE Direct revenues represented approximately …% of total NIKE Brand revenues” | N58: NIKE Direct revenues grew 1% from $21.3 billion in fiscal 2023 to $21.5 billion in fiscal 2024, and represented approximately 44% of total NIKE Brand revenues for fiscal 2024 | O58: Khớp với giá trị tự tính từ BCTC (chênh −0,37 điểm %, ngưỡng ±1 điểm %). | P58: 10-K năm sau không trình bày lại số này. | T58: NIKE Direct as approx. % of total NIKE Brand revenues (as stated) | U58: Không gắn thẻ XBRL (MD&A) | V58: 01/06/2023 – 31/05/2024 | W58: 25/07/2024 | X58: 0000320187-24-000044 | Y58: nike_direct_share_stated | Z58: FY2024|nike_direct_share_stated
A59: FY2025 | B59: Tỷ trọng NIKE Direct do NIKE nêu (xấp xỉ) | C59: 0.42 | E59: % | F59: NIKE Brand | G59: NIKE Direct | H59: MD&A – ban điều hành nêu, không kiểm toán | I59: Khớp nguồn chính thức | J59: 10-K FY2025 | K59: 29 | L59: ITEM 7 – MD&A | M59: Item 7 – MD&A, câu “NIKE Direct revenues represented approximately …% of total NIKE Brand revenues” | N59: NIKE Direct revenues declined 13% from $21.5 billion in fiscal 2024 to $18.8 billion in fiscal 2025, and represented approximately 42% of total NIKE Brand revenues for fiscal 2025 | O59: Khớp với giá trị tự tính từ BCTC (chênh +0,01 điểm %, ngưỡng ±1 điểm %). | P59: 10-K năm sau không trình bày lại số này. | T59: NIKE Direct as approx. % of total NIKE Brand revenues (as stated) | U59: Không gắn thẻ XBRL (MD&A) | V59: 01/06/2024 – 31/05/2025 | W59: 17/07/2025 | X59: 0000320187-25-000047 | Y59: nike_direct_share_stated | Z59: FY2025|nike_direct_share_stated
A60: FY2026 | B60: Tỷ trọng NIKE Direct do NIKE nêu (xấp xỉ) | E60: % | F60: NIKE Brand | G60: NIKE Direct | H60: MD&A – ban điều hành nêu, không kiểm toán | I60: Thiếu / không công bố | J60: 10-K FY2026 | L60: — | M60: Item 7 – MD&A, câu “NIKE Direct revenues represented approximately …% of total NIKE Brand revenues” | N60: — | O60: 10-K FY2026 không công bố chỉ tiêu này. | P60: — | T60: NIKE Direct as approx. % of total NIKE Brand revenues (as stated) | U60: Không gắn thẻ XBRL (MD&A) | V60: 01/06/2025 – 31/05/2026 | W60: 15/07/2026 | X60: 0000320187-26-000088 | Y60: nike_direct_share_stated | Z60: FY2026|nike_direct_share_stated
A61: FY2020 | B61: % thay đổi NIKE Direct (NIKE công bố, đã làm tròn) | C61: 0.05 | E61: % | F61: NIKE Brand | G61: NIKE Direct | H61: MD&A – % tính từ số GAAP | I61: Khớp nguồn chính thức | J61: 10-K FY2020 | K61: 31 | L61: ITEM 7 – MD&A | M61: Item 7 – MD&A, bảng doanh thu, mục Supplemental NIKE Brand Revenues Details, cột “% CHANGE” | N61: Sales through NIKE Direct | 12,382 | 11,753 | 5 | 8 | 10,428 | 13 | 16 | O61: Khớp với giá trị tự tính từ BCTC (chênh +0,35 điểm %, ngưỡng ±1 điểm %). | P61: Không áp dụng: tỷ lệ % chỉ lấy từ 10-K của chính năm đó. | T61: Sales through NIKE Direct – % change | U61: Không gắn thẻ XBRL (MD&A) | V61: 01/06/2019 – 31/05/2020 | W61: 24/07/2020 | X61: 0000320187-20-000047 | Y61: nike_direct_pct_change_reported | Z61: FY2020|nike_direct_pct_change_reported
A62: FY2021 | B62: % thay đổi NIKE Direct (NIKE công bố, đã làm tròn) | C62: 0.32 | E62: % | F62: NIKE Brand | G62: NIKE Direct | H62: MD&A – % tính từ số GAAP | I62: Khớp nguồn chính thức | J62: 10-K FY2021 | K62: 32 | L62: ITEM 7 – MD&A | M62: Item 7 – MD&A, bảng doanh thu, mục Supplemental NIKE Brand Revenues Details, cột “% CHANGE” | N62: Sales through NIKE Direct | 16,370 | 12,382 | 32 | 30 | 11,753 | 5 | 8 | O62: Khớp với giá trị tự tính từ BCTC (chênh +0,21 điểm %, ngưỡng ±1 điểm %). | P62: Không áp dụng: tỷ lệ % chỉ lấy từ 10-K của chính năm đó. | T62: Sales through NIKE Direct – % change | U62: Không gắn thẻ XBRL (MD&A) | V62: 01/06/2020 – 31/05/2021 | W62: 20/07/2021 | X62: 0000320187-21-000028 | Y62: nike_direct_pct_change_reported | Z62: FY2021|nike_direct_pct_change_reported
A63: FY2022 | B63: % thay đổi NIKE Direct (NIKE công bố, đã làm tròn) | C63: 0.14 | E63: % | F63: NIKE Brand | G63: NIKE Direct | H63: MD&A – % tính từ số GAAP | I63: Khớp nguồn chính thức | J63: 10-K FY2022 | K63: 32 | L63: ITEM 7 – MD&A | M63: Item 7 – MD&A, bảng doanh thu, mục Supplemental NIKE Brand Revenues Details, cột “% CHANGE” | N63: Sales through NIKE Direct | 18,726 | 16,370 | 14 | 15 | 12,382 | 32 | 30 | O63: Khớp với giá trị tự tính từ BCTC (chênh +0,39 điểm %, ngưỡng ±1 điểm %). | P63: Không áp dụng: tỷ lệ % chỉ lấy từ 10-K của chính năm đó. | T63: Sales through NIKE Direct – % change | U63: Không gắn thẻ XBRL (MD&A) | V63: 01/06/2021 – 31/05/2022 | W63: 21/07/2022 | X63: 0000320187-22-000038 | Y63: nike_direct_pct_change_reported | Z63: FY2022|nike_direct_pct_change_reported
A64: FY2023 | B64: % thay đổi NIKE Direct (NIKE công bố, đã làm tròn) | C64: 0.14 | E64: % | F64: NIKE Brand | G64: NIKE Direct | H64: MD&A – % tính từ số GAAP | I64: Khớp nguồn chính thức | J64: 10-K FY2023 | K64: 32 | L64: ITEM 7 – MD&A | M64: Item 7 – MD&A, bảng doanh thu, mục Supplemental NIKE Brand Revenues Details, cột “% CHANGE” | N64: Sales through NIKE Direct | 21,308 | 18,726 | 14 | 20 | 16,370 | 14 | 15 | O64: Khớp với giá trị tự tính từ BCTC (chênh −0,21 điểm %, ngưỡng ±1 điểm %). | P64: Không áp dụng: tỷ lệ % chỉ lấy từ 10-K của chính năm đó. | T64: Sales through NIKE Direct – % change | U64: Không gắn thẻ XBRL (MD&A) | V64: 01/06/2022 – 31/05/2023 | W64: 20/07/2023 | X64: 0000320187-23-000039 | Y64: nike_direct_pct_change_reported | Z64: FY2023|nike_direct_pct_change_reported
A65: FY2024 | B65: % thay đổi NIKE Direct (NIKE công bố, đã làm tròn) | C65: 0.01 | E65: % | F65: NIKE Brand | G65: NIKE Direct | H65: MD&A – % tính từ số GAAP | I65: Khớp nguồn chính thức | J65: 10-K FY2024 | K65: 34 | L65: ITEM 7 – MD&A | M65: Item 7 – MD&A, bảng doanh thu, mục Supplemental NIKE Brand Revenues Details, cột “% CHANGE” | N65: Sales through NIKE Direct | 21,519 | 21,308 | 1 | 1 | 18,726 | 14 | 20 | O65: Khớp với giá trị tự tính từ BCTC (chênh −0,01 điểm %, ngưỡng ±1 điểm %). | P65: Không áp dụng: tỷ lệ % chỉ lấy từ 10-K của chính năm đó. | T65: Sales through NIKE Direct – % change | U65: Không gắn thẻ XBRL (MD&A) | V65: 01/06/2023 – 31/05/2024 | W65: 25/07/2024 | X65: 0000320187-24-000044 | Y65: nike_direct_pct_change_reported | Z65: FY2024|nike_direct_pct_change_reported
A66: FY2025 | B66: % thay đổi NIKE Direct (NIKE công bố, đã làm tròn) | C66: -0.13 | E66: % | F66: NIKE Brand | G66: NIKE Direct | H66: MD&A – % tính từ số GAAP | I66: Khớp nguồn chính thức | J66: 10-K FY2025 | K66: 33 | L66: ITEM 7 – MD&A | M66: Item 7 – MD&A, bảng doanh thu, mục Supplemental NIKE Brand Revenues Details, cột “% CHANGE” | N66: Sales through NIKE Direct | 18,783 | 21,519 | -13 | -12 | 21,308 | 1 | 1 | O66: Khớp với giá trị tự tính từ BCTC (chênh +0,29 điểm %, ngưỡng ±1 điểm %). | P66: Không áp dụng: tỷ lệ % chỉ lấy từ 10-K của chính năm đó. | T66: Sales through NIKE Direct – % change | U66: Không gắn thẻ XBRL (MD&A) | V66: 01/06/2024 – 31/05/2025 | W66: 17/07/2025 | X66: 0000320187-25-000047 | Y66: nike_direct_pct_change_reported | Z66: FY2025|nike_direct_pct_change_reported
A67: FY2026 | B67: % thay đổi NIKE Direct (NIKE công bố, đã làm tròn) | C67: -0.06 | E67: % | F67: NIKE Brand | G67: NIKE Direct | H67: MD&A – % tính từ số GAAP | I67: Khớp nguồn chính thức | J67: 10-K FY2026 | K67: 32 | L67: ITEM 7 – MD&A | M67: Item 7 – MD&A, bảng doanh thu, mục Supplemental NIKE Brand Revenues Details, cột “% CHANGE” | N67: Sales through NIKE Direct | 17,720 | 18,783 | -6 | -8 | 21,519 | -13 | -12 | O67: Khớp với giá trị tự tính từ BCTC (chênh +0,34 điểm %, ngưỡng ±1 điểm %). | P67: Không áp dụng: tỷ lệ % chỉ lấy từ 10-K của chính năm đó. | T67: Sales through NIKE Direct – % change | U67: Không gắn thẻ XBRL (MD&A) | V67: 01/06/2025 – 31/05/2026 | W67: 15/07/2026 | X67: 0000320187-26-000088 | Y67: nike_direct_pct_change_reported | Z67: FY2026|nike_direct_pct_change_reported
A68: FY2020 | B68: % thay đổi NIKE Direct loại trừ tỷ giá | C68: 0.08 | E68: % | F68: NIKE Brand | G68: NIKE Direct | H68: Non-GAAP – NIKE định nghĩa | I68: Khớp nguồn chính thức | J68: 10-K FY2020 | K68: 31 | L68: ITEM 7 – MD&A | M68: Item 7 – MD&A, bảng doanh thu, mục Supplemental NIKE Brand Revenues Details, cột “% CHANGE EXCLUDING CURRENCY CHANGES” | N68: Sales through NIKE Direct | 12,382 | 11,753 | 5 | 8 | 10,428 | 13 | 16 | O68: Đã đọc lại ngay trên trang 10-K (tr. 31): khớp. Ảnh chụp đối chiếu: handover/bang-chung-doi-chieu/FY2020-bang-doanh-thu-tr31.png. | P68: Không áp dụng: tỷ lệ % chỉ lấy từ 10-K của chính năm đó. | T68: Sales through NIKE Direct – % change excluding currency changes | U68: Không gắn thẻ XBRL (MD&A) | V68: 01/06/2019 – 31/05/2020 | W68: 24/07/2020 | X68: 0000320187-20-000047 | Y68: nike_direct_pct_change_cn | Z68: FY2020|nike_direct_pct_change_cn
A69: FY2021 | B69: % thay đổi NIKE Direct loại trừ tỷ giá | C69: 0.3 | E69: % | F69: NIKE Brand | G69: NIKE Direct | H69: Non-GAAP – NIKE định nghĩa | I69: Khớp nguồn chính thức | J69: 10-K FY2021 | K69: 32 | L69: ITEM 7 – MD&A | M69: Item 7 – MD&A, bảng doanh thu, mục Supplemental NIKE Brand Revenues Details, cột “% CHANGE EXCLUDING CURRENCY CHANGES” | N69: Sales through NIKE Direct | 16,370 | 12,382 | 32 | 30 | 11,753 | 5 | 8 | O69: Đã đọc lại ngay trên trang 10-K (tr. 32): khớp. Ảnh chụp đối chiếu: handover/bang-chung-doi-chieu/FY2021-bang-doanh-thu-tr32.png. | P69: Không áp dụng: tỷ lệ % chỉ lấy từ 10-K của chính năm đó. | T69: Sales through NIKE Direct – % change excluding currency changes | U69: Không gắn thẻ XBRL (MD&A) | V69: 01/06/2020 – 31/05/2021 | W69: 20/07/2021 | X69: 0000320187-21-000028 | Y69: nike_direct_pct_change_cn | Z69: FY2021|nike_direct_pct_change_cn
A70: FY2022 | B70: % thay đổi NIKE Direct loại trừ tỷ giá | C70: 0.15 | E70: % | F70: NIKE Brand | G70: NIKE Direct | H70: Non-GAAP – NIKE định nghĩa | I70: Khớp nguồn chính thức | J70: 10-K FY2022 | K70: 32 | L70: ITEM 7 – MD&A | M70: Item 7 – MD&A, bảng doanh thu, mục Supplemental NIKE Brand Revenues Details, cột “% CHANGE EXCLUDING CURRENCY CHANGES” | N70: Sales through NIKE Direct | 18,726 | 16,370 | 14 | 15 | 12,382 | 32 | 30 | O70: Đã đọc lại ngay trên trang 10-K (tr. 32): khớp. Ảnh chụp đối chiếu: handover/bang-chung-doi-chieu/FY2022-bang-doanh-thu-tr32.png. | P70: Không áp dụng: tỷ lệ % chỉ lấy từ 10-K của chính năm đó. | T70: Sales through NIKE Direct – % change excluding currency changes | U70: Không gắn thẻ XBRL (MD&A) | V70: 01/06/2021 – 31/05/2022 | W70: 21/07/2022 | X70: 0000320187-22-000038 | Y70: nike_direct_pct_change_cn | Z70: FY2022|nike_direct_pct_change_cn
A71: FY2023 | B71: % thay đổi NIKE Direct loại trừ tỷ giá | C71: 0.2 | E71: % | F71: NIKE Brand | G71: NIKE Direct | H71: Non-GAAP – NIKE định nghĩa | I71: Khớp nguồn chính thức | J71: 10-K FY2023 | K71: 32 | L71: ITEM 7 – MD&A | M71: Item 7 – MD&A, bảng doanh thu, mục Supplemental NIKE Brand Revenues Details, cột “% CHANGE EXCLUDING CURRENCY CHANGES” | N71: Sales through NIKE Direct | 21,308 | 18,726 | 14 | 20 | 16,370 | 14 | 15 | O71: Đã đọc lại ngay trên trang 10-K (tr. 32): khớp. Ảnh chụp đối chiếu: handover/bang-chung-doi-chieu/FY2023-bang-doanh-thu-tr32.png. | P71: Không áp dụng: tỷ lệ % chỉ lấy từ 10-K của chính năm đó. | T71: Sales through NIKE Direct – % change excluding currency changes | U71: Không gắn thẻ XBRL (MD&A) | V71: 01/06/2022 – 31/05/2023 | W71: 20/07/2023 | X71: 0000320187-23-000039 | Y71: nike_direct_pct_change_cn | Z71: FY2023|nike_direct_pct_change_cn
A72: FY2024 | B72: % thay đổi NIKE Direct loại trừ tỷ giá | C72: 0.01 | E72: % | F72: NIKE Brand | G72: NIKE Direct | H72: Non-GAAP – NIKE định nghĩa | I72: Khớp nguồn chính thức | J72: 10-K FY2024 | K72: 34 | L72: ITEM 7 – MD&A | M72: Item 7 – MD&A, bảng doanh thu, mục Supplemental NIKE Brand Revenues Details, cột “% CHANGE EXCLUDING CURRENCY CHANGES” | N72: Sales through NIKE Direct | 21,519 | 21,308 | 1 | 1 | 18,726 | 14 | 20 | O72: Đã đọc lại ngay trên trang 10-K (tr. 34): khớp. Ảnh chụp đối chiếu: handover/bang-chung-doi-chieu/FY2024-bang-doanh-thu-tr34.png. | P72: Không áp dụng: tỷ lệ % chỉ lấy từ 10-K của chính năm đó. | T72: Sales through NIKE Direct – % change excluding currency changes | U72: Không gắn thẻ XBRL (MD&A) | V72: 01/06/2023 – 31/05/2024 | W72: 25/07/2024 | X72: 0000320187-24-000044 | Y72: nike_direct_pct_change_cn | Z72: FY2024|nike_direct_pct_change_cn
... A102: FY2026 | B102: % thay đổi NIKE Brand loại trừ tỷ giá | C102: -0.01 | E102: % | F102: NIKE Brand | G102: Tổng NIKE Brand | H102: Non-GAAP – NIKE định nghĩa | I102: Khớp nguồn chính thức | J102: 10-K FY2026 | K102: 32 | L102: ITEM 7 – MD&A | M102: Item 7 – MD&A, bảng doanh thu, mục Supplemental NIKE Brand Revenues Details, cột “% CHANGE EXCLUDING CURRENCY CHANGES” | N102: TOTAL NIKE BRAND REVENUES(3) | 45,222 | 44,714 | 1 | -1 | 49,322 | -9 | -9 | O102: Đã đọc lại ngay trên trang 10-K (tr. 32): khớp. Ảnh chụp đối chiếu: handover/bang-chung-doi-chieu/FY2026-bang-doanh-thu-tr32.png. | P102: Không áp dụng: tỷ lệ % chỉ lấy từ 10-K của chính năm đó. | T102: TOTAL NIKE BRAND REVENUES – % change excluding currency changes | U102: Không gắn thẻ XBRL (MD&A) | V102: 01/06/2025 – 31/05/2026 | W102: 15/07/2026 | X102: 0000320187-26-000088 | Y102: nike_brand_pct_change_cn | Z102: FY2026|nike_brand_pct_change_cn

Sheet 04 KPI & Tính toán
A1: Chỉ số tính toán (KPI) và kiểm tra đối chiếu
A2: Mọi ô số trong sheet này là công thức Excel. Số màu xanh lá lấy từ sheet 02/03 theo năm và mã chỉ tiêu, số màu đen được tính ngay trong sheet này. Sửa số liệu ở sheet 02/03 thì sheet này tự cập nhật. “–” nghĩa là thiếu số liệu đầu vào, không phải bằng 0.
A4: Mã | B4: Chỉ tiêu | C4: Đơn vị | D4: FY2020 | E4: FY2021 | F4: FY2022 | G4: FY2023 | H4: FY2024 | I4: FY2025 | J4: FY2026 | K4: Công thức | L4: Ghi chú và cách đọc
B6: A. Số liệu đầu vào (lấy từ sheet 02 và 03)
A7: revenues | B7: Doanh thu | C7: triệu USD | D7: =IF(INDEX('02 Dữ liệu tài chính'!$C$5:$C$401,MATCH(D$4&"|revenues",'02 Dữ liệu tài chính'!$Z$5:$Z$401,0))="","–",INDEX('02 Dữ liệu tài chính'!$C$5:$C$401,MATCH(D$4&"|revenues",'02 Dữ liệu tài chính'!$Z$5:$Z$401,0))) -> 37403 | E7: =IF(INDEX('02 Dữ liệu tài chính'!$C$5:$C$401,MATCH(E$4&"|revenues",'02 Dữ liệu tài chính'!$Z$5:$Z$401,0))="","–",INDEX('02 Dữ liệu tài chính'!$C$5:$C$401,MATCH(E$4&"|revenues",'02 Dữ liệu tài chính'!$Z$5:$Z$401,0))) -> 44538 | F7: =IF(INDEX('02 Dữ liệu tài chính'!$C$5:$C$401,MATCH(F$4&"|revenues",'02 Dữ liệu tài chính'!$Z$5:$Z$401,0))="","–",INDEX('02 Dữ liệu tài chính'!$C$5:$C$401,MATCH(F$4&"|revenues",'02 Dữ liệu tài chính'!$Z$5:$Z$401,0))) -> 46710 | G7: =IF(INDEX('02 Dữ liệu tài chính'!$C$5:$C$401,MATCH(G$4&"|revenues",'02 Dữ liệu tài chính'!$Z$5:$Z$401,0))="","–",INDEX('02 Dữ liệu tài chính'!$C$5:$C$401,MATCH(G$4&"|revenues",'02 Dữ liệu tài chính'!$Z$5:$Z$401,0))) -> 51217 | H7: =IF(INDEX('02 Dữ liệu tài chính'!$C$5:$C$401,MATCH(H$4&"|revenues",'02 Dữ liệu tài chính'!$Z$5:$Z$401,0))="","–",INDEX('02 Dữ liệu tài chính'!$C$5:$C$401,MATCH(H$4&"|revenues",'02 Dữ liệu tài chính'!$Z$5:$Z$401,0))) -> 51362 | I7: =IF(INDEX('02 Dữ liệu tài chính'!$C$5:$C$401,MATCH(I$4&"|revenues",'02 Dữ liệu tài chính'!$Z$5:$Z$401,0))="","–",INDEX('02 Dữ liệu tài chính'!$C$5:$C$401,MATCH(I$4&"|revenues",'02 Dữ liệu tài chính'!$Z$5:$Z$401,0))) -> 46309 | J7: =IF(INDEX('02 Dữ liệu tài chính'!$C$5:$C$401,MATCH(J$4&"|revenues",'02 Dữ liệu tài chính'!$Z$5:$Z$401,0))="","–",INDEX('02 Dữ liệu tài chính'!$C$5:$C$401,MATCH(J$4&"|revenues",'02 Dữ liệu tài chính'!$Z$5:$Z$401,0))) -> 46398 | K7: Tra cứu sheet “02 Dữ liệu tài chính” theo khóa FY|revenues, cột “Giá trị”.
A8: revenues__prior | B8: Doanh thu – năm trước (cùng 10-K) | C8: triệu USD | D8: =IF(INDEX('02 Dữ liệu tài chính'!$D$5:$D$401,MATCH(D$4&"|revenues",'02 Dữ liệu tài chính'!$Z$5:$Z$401,0))="","–",INDEX('02 Dữ liệu tài chính'!$D$5:$D$401,MATCH(D$4&"|revenues",'02 Dữ liệu tài chính'!$Z$5:$Z$401,0))) -> 39117 | E8: =IF(INDEX('02 Dữ liệu tài chính'!$D$5:$D$401,MATCH(E$4&"|revenues",'02 Dữ liệu tài chính'!$Z$5:$Z$401,0))="","–",INDEX('02 Dữ liệu tài chính'!$D$5:$D$401,MATCH(E$4&"|revenues",'02 Dữ liệu tài chính'!$Z$5:$Z$401,0))) -> 37403 | F8: =IF(INDEX('02 Dữ liệu tài chính'!$D$5:$D$401,MATCH(F$4&"|revenues",'02 Dữ liệu tài chính'!$Z$5:$Z$401,0))="","–",INDEX('02 Dữ liệu tài chính'!$D$5:$D$401,MATCH(F$4&"|revenues",'02 Dữ liệu tài chính'!$Z$5:$Z$401,0))) -> 44538 | G8: =IF(INDEX('02 Dữ liệu tài chính'!$D$5:$D$401,MATCH(G$4&"|revenues",'02 Dữ liệu tài chính'!$Z$5:$Z$401,0))="","–",INDEX('02 Dữ liệu tài chính'!$D$5:$D$401,MATCH(G$4&"|revenues",'02 Dữ liệu tài chính'!$Z$5:$Z$401,0))) -> 46710 | H8: =IF(INDEX('02 Dữ liệu tài chính'!$D$5:$D$401,MATCH(H$4&"|revenues",'02 Dữ liệu tài chính'!$Z$5:$Z$401,0))="","–",INDEX('02 Dữ liệu tài chính'!$D$5:$D$401,MATCH(H$4&"|revenues",'02 Dữ liệu tài chính'!$Z$5:$Z$401,0))) -> 51217 | I8: =IF(INDEX('02 Dữ liệu tài chính'!$D$5:$D$401,MATCH(I$4&"|revenues",'02 Dữ liệu tài chính'!$Z$5:$Z$401,0))="","–",INDEX('02 Dữ liệu tài chính'!$D$5:$D$401,MATCH(I$4&"|revenues",'02 Dữ liệu tài chính'!$Z$5:$Z$401,0))) -> 51362 | J8: =IF(INDEX('02 Dữ liệu tài chính'!$D$5:$D$401,MATCH(J$4&"|revenues",'02 Dữ liệu tài chính'!$Z$5:$Z$401,0))="","–",INDEX('02 Dữ liệu tài chính'!$D$5:$D$401,MATCH(J$4&"|revenues",'02 Dữ liệu tài chính'!$Z$5:$Z$401,0))) -> 46309 | K8: Tra cứu sheet “02 Dữ liệu tài chính” theo khóa FY|revenues, cột “Giá trị năm trước (cùng 10-K)”.
A9: cost_of_sales | B9: Giá vốn hàng bán | C9: triệu USD | D9: =IF(INDEX('02 Dữ liệu tài chính'!$C$5:$C$401,MATCH(D$4&"|cost_of_sales",'02 Dữ liệu tài chính'!$Z$5:$Z$401,0))="","–",INDEX('02 Dữ liệu tài chính'!$C$5:$C$401,MATCH(D$4&"|cost_of_sales",'02 Dữ liệu tài chính'!$Z$5:$Z$401,0))) -> 21162 | E9: =IF(INDEX('02 Dữ liệu tài chính'!$C$5:$C$401,MATCH(E$4&"|cost_of_sales",'02 Dữ liệu tài chính'!$Z$5:$Z$401,0))="","–",INDEX('02 Dữ liệu tài chính'!$C$5:$C$401,MATCH(E$4&"|cost_of_sales",'02 Dữ liệu tài chính'!$Z$5:$Z$401,0))) -> 24576 | F9: =IF(INDEX('02 Dữ liệu tài chính'!$C$5:$C$401,MATCH(F$4&"|cost_of_sales",'02 Dữ liệu tài chính'!$Z$5:$Z$401,0))="","–",INDEX('02 Dữ liệu tài chính'!$C$5:$C$401,MATCH(F$4&"|cost_of_sales",'02 Dữ liệu tài chính'!$Z$5:$Z$401,0))) -> 25231 | G9: =IF(INDEX('02 Dữ liệu tài chính'!$C$5:$C$401,MATCH(G$4&"|cost_of_sales",'02 Dữ liệu tài chính'!$Z$5:$Z$401,0))="","–",INDEX('02 Dữ liệu tài chính'!$C$5:$C$401,MATCH(G$4&"|cost_of_sales",'02 Dữ liệu tài chính'!$Z$5:$Z$401,0))) -> 28925 | H9: =IF(INDEX('02 Dữ liệu tài chính'!$C$5:$C$401,MATCH(H$4&"|cost_of_sales",'02 Dữ liệu tài chính'!$Z$5:$Z$401,0))="","–",INDEX('02 Dữ liệu tài chính'!$C$5:$C$401,MATCH(H$4&"|cost_of_sales",'02 Dữ liệu tài chính'!$Z$5:$Z$401,0))) -> 28475 | I9: =IF(INDEX('02 Dữ liệu tài chính'!$C$5:$C$401,MATCH(I$4&"|cost_of_sales",'02 Dữ liệu tài chính'!$Z$5:$Z$401,0))="","–",INDEX('02 Dữ liệu tài chính'!$C$5:$C$401,MATCH(I$4&"|cost_of_sales",'02 Dữ liệu tài chính'!$Z$5:$Z$401,0))) -> 26519 | J9: =IF(INDEX('02 Dữ liệu tài chính'!$C$5:$C$401,MATCH(J$4&"|cost_of_sales",'02 Dữ liệu tài chính'!$Z$5:$Z$401,0))="","–",INDEX('02 Dữ liệu tài chính'!$C$5:$C$401,MATCH(J$4&"|cost_of_sales",'02 Dữ liệu tài chính'!$Z$5:$Z$401,0))) -> 26487 | K9: Tra cứu sheet “02 Dữ liệu tài chính” theo khóa FY|cost_of_sales, cột “Giá trị”.
