Workbook
Name Slicer_Cơ_sở_tính_tăng_trưởng: #N/A
Name Slicer_Năm_tài_chính: #N/A

Sheet Chiến lược phân phối
B2: Phân phối và kết quả tài chính của NIKE, FY2020–FY2026 | M2: Tải bộ dữ liệu Excel
B3: Số liệu lấy từ báo cáo thường niên Form 10‑K mà NIKE, Inc. nộp cho Ủy ban Chứng khoán Mỹ (SEC). Năm tài chính của NIKE kết thúc ngày 31/5. | M3: Nguồn và phương pháp
M4: Mở dashboard web
B6: Chiến lược phân phối | D6: Kết quả tài chính
J8: Bấm một năm để lọc, giữ Ctrl để chọn nhiều năm. Bấm nút xóa lọc ở góc slicer để xem lại đủ 7 năm.
B12: Cơ cấu doanh thu giữa NIKE Direct và bán buôn đã thay đổi thế nào trong FY2020–FY2026? | I12: Tóm tắt theo khoảng năm đang chọn
I13: ='Dữ liệu biểu đồ'!$C$27 -> Tỷ trọng NIKE Direct trong doanh thu NIKE Brand là 34,8% ở FY2020 và 39,2% ở FY2026, cao nhất 43,7% (FY2023). Doanh thu NIKE Direct đi từ 12,4 đến 17,7 tỷ USD, còn bán buôn từ 23,2 đến 27,5 tỷ USD.
B19: Cơ cấu doanh thu NIKE Brand theo kênh
B20: Tỷ trọng trong tổng doanh thu NIKE Brand (%), do nhóm tự tính từ số liệu 10‑K.
B38: ="Nguồn: thuyết minh “Revenues” trong Form 10‑K (bảng phân tách doanh thu, cột Total NIKE Brand). Tỷ trọng do nhóm tự tính."&'Dữ liệu biểu đồ'!$C$31 -> Nguồn: thuyết minh “Revenues” trong Form 10‑K (bảng phân tách doanh thu, cột Total NIKE Brand). Tỷ trọng do nhóm tự tính. Báo cáo: 10‑K FY2020–FY2026 (danh sách ở sheet “Nguồn và phương pháp”).
B40: Doanh thu theo kênh | H40: Tăng trưởng so với năm trước
B41: Tỷ USD, phạm vi NIKE Brand. Số do NIKE công bố. | H41: ='Dữ liệu biểu đồ'!$C$29 -> Thay đổi so với năm trước (%), theo báo cáo, phạm vi NIKE Brand. Nhóm tự tính từ 10‑K.
B59: ="Nguồn: thuyết minh “Revenues” trong Form 10‑K."&'Dữ liệu biểu đồ'!$C$31 -> Nguồn: thuyết minh “Revenues” trong Form 10‑K. Báo cáo: 10‑K FY2020–FY2026 (danh sách ở sheet “Nguồn và phương pháp”). | H59: ='Dữ liệu biểu đồ'!$C$30&'Dữ liệu biểu đồ'!$C$31 -> Nguồn: thuyết minh “Revenues” trong Form 10‑K. Tăng trưởng tính từ số năm nay và số năm trước trong cùng 10‑K. Báo cáo: 10‑K FY2020–FY2026 (danh sách ở sheet “Nguồn và phương pháp”).
B61: NIKE Brand Digital trong NIKE Direct | H61: Cách đọc số liệu kênh NIKE Brand, không phải NIKE, Inc. Tỷ trọng các kênh được tính trên tổng doanh thu NIKE Brand. Converse (có kênh bán trực tiếp riêng) và Corporate không nằm trong các con số này. NIKE Direct gồm cửa hàng và Digital NIKE chỉ công bố doanh số Digital trong phần MD&A và làm tròn đến 0,1 tỷ USD. Trong 10‑K FY2024, số FY2023 được trình bày lại từ 12,6 xuống 12,4 tỷ USD, nên khi so FY2024 (12,1 tỷ USD) với năm trước cần dùng số 12,4 để cùng cách phân loại. Theo báo cáo và loại trừ tỷ giá Tăng trưởng theo báo cáo được tính từ doanh thu năm nay và số năm trước trong cùng 10‑K. Tăng trưởng loại trừ tỷ giá là chỉ tiêu non‑GAAP do NIKE tính, nhóm không tự tính lại được. Doanh thu không phải lợi nhuận NIKE không công bố lợi nhuận hay chi phí riêng của từng kênh, nên trang này không so sánh khả năng sinh lời giữa các kênh.
B62: Tỷ USD. Digital là một phần của NIKE Direct (cùng với cửa hàng do NIKE sở hữu).
B78: ="Nguồn: MD&A (Item 7), đoạn nói về NIKE Direct. Số NIKE Direct lấy từ thuyết minh “Revenues”."&'Dữ liệu biểu đồ'!$C$31 -> Nguồn: MD&A (Item 7), đoạn nói về NIKE Direct. Số NIKE Direct lấy từ thuyết minh “Revenues”. Báo cáo: 10‑K FY2020–FY2026 (danh sách ở sheet “Nguồn và phương pháp”).
B80: Bảng số liệu kênh phân phối
B81: Số NIKE công bố có số trang 10‑K ở dòng nhỏ ngay dưới (bấm vào số trang để mở báo cáo trên SEC). Số in nghiêng là số nhóm tự tính.
B82: Chỉ tiêu | E82: Đơn vị | F82: =IFERROR(_xlfn.AGGREGATE(15,5,'Dữ liệu biểu đồ'!$B$5:$B$11,1),"") -> 2020 | G82: =IFERROR(_xlfn.AGGREGATE(15,5,'Dữ liệu biểu đồ'!$B$5:$B$11,2),"") -> 2021 | H82: =IFERROR(_xlfn.AGGREGATE(15,5,'Dữ liệu biểu đồ'!$B$5:$B$11,3),"") -> 2022 | I82: =IFERROR(_xlfn.AGGREGATE(15,5,'Dữ liệu biểu đồ'!$B$5:$B$11,4),"") -> 2023 | J82: =IFERROR(_xlfn.AGGREGATE(15,5,'Dữ liệu biểu đồ'!$B$5:$B$11,5),"") -> 2024 | K82: =IFERROR(_xlfn.AGGREGATE(15,5,'Dữ liệu biểu đồ'!$B$5:$B$11,6),"") -> 2025 | L82: =IFERROR(_xlfn.AGGREGATE(15,5,'Dữ liệu biểu đồ'!$B$5:$B$11,7),"") -> 2026
B83: Doanh thu NIKE Brand
B84: NIKE Direct | E84: triệu USD | F84: =IF(F$82="","",INDEX('Dữ liệu biểu đồ'!$C$47:$I$47,F$82-2019)) -> 12.382 | G84: =IF(G$82="","",INDEX('Dữ liệu biểu đồ'!$C$47:$I$47,G$82-2019)) -> 16.370 | H84: =IF(H$82="","",INDEX('Dữ liệu biểu đồ'!$C$47:$I$47,H$82-2019)) -> 18.726 | I84: =IF(I$82="","",INDEX('Dữ liệu biểu đồ'!$C$47:$I$47,I$82-2019)) -> 21.308 | J84: =IF(J$82="","",INDEX('Dữ liệu biểu đồ'!$C$47:$I$47,J$82-2019)) -> 21.519 | K84: =IF(K$82="","",INDEX('Dữ liệu biểu đồ'!$C$47:$I$47,K$82-2019)) -> 18.783 | L84: =IF(L$82="","",INDEX('Dữ liệu biểu đồ'!$C$47:$I$47,L$82-2019)) -> 17.720
F85: =IF(F$82="","",IF(INDEX('Dữ liệu biểu đồ'!$J$47:$P$47,F$82-2019)="",INDEX('Dữ liệu biểu đồ'!$C$48:$I$48,F$82-2019)&"",HYPERLINK(INDEX('Dữ liệu biểu đồ'!$J$47:$P$47,F$82-2019),INDEX('Dữ liệu biểu đồ'!$C$48:$I$48,F$82-2019)))) -> tr. 88 | G85: =IF(G$82="","",IF(INDEX('Dữ liệu biểu đồ'!$J$47:$P$47,G$82-2019)="",INDEX('Dữ liệu biểu đồ'!$C$48:$I$48,G$82-2019)&"",HYPERLINK(INDEX('Dữ liệu biểu đồ'!$J$47:$P$47,G$82-2019),INDEX('Dữ liệu biểu đồ'!$C$48:$I$48,G$82-2019)))) -> tr. 86 | H85: =IF(H$82="","",IF(INDEX('Dữ liệu biểu đồ'!$J$47:$P$47,H$82-2019)="",INDEX('Dữ liệu biểu đồ'!$C$48:$I$48,H$82-2019)&"",HYPERLINK(INDEX('Dữ liệu biểu đồ'!$J$47:$P$47,H$82-2019),INDEX('Dữ liệu biểu đồ'!$C$48:$I$48,H$82-2019)))) -> tr. 85 | I85: =IF(I$82="","",IF(INDEX('Dữ liệu biểu đồ'!$J$47:$P$47,I$82-2019)="",INDEX('Dữ liệu biểu đồ'!$C$48:$I$48,I$82-2019)&"",HYPERLINK(INDEX('Dữ liệu biểu đồ'!$J$47:$P$47,I$82-2019),INDEX('Dữ liệu biểu đồ'!$C$48:$I$48,I$82-2019)))) -> tr. 83 | J85: =IF(J$82="","",IF(INDEX('Dữ liệu biểu đồ'!$J$47:$P$47,J$82-2019)="",INDEX('Dữ liệu biểu đồ'!$C$48:$I$48,J$82-2019)&"",HYPERLINK(INDEX('Dữ liệu biểu đồ'!$J$47:$P$47,J$82-2019),INDEX('Dữ liệu biểu đồ'!$C$48:$I$48,J$82-2019)))) -> tr. 84 | K85: =IF(K$82="","",IF(INDEX('Dữ liệu biểu đồ'!$J$47:$P$47,K$82-2019)="",INDEX('Dữ liệu biểu đồ'!$C$48:$I$48,K$82-2019)&"",HYPERLINK(INDEX('Dữ liệu biểu đồ'!$J$47:$P$47,K$82-2019),INDEX('Dữ liệu biểu đồ'!$C$48:$I$48,K$82-2019)))) -> tr. 82 | L85: =IF(L$82="","",IF(INDEX('Dữ liệu biểu đồ'!$J$47:$P$47,L$82-2019)="",INDEX('Dữ liệu biểu đồ'!$C$48:$I$48,L$82-2019)&"",HYPERLINK(INDEX('Dữ liệu biểu đồ'!$J$47:$P$47,L$82-2019),INDEX('Dữ liệu biểu đồ'!$C$48:$I$48,L$82-2019)))) -> tr. 83
B86: Bán buôn (Wholesale) | E86: triệu USD | F86: =IF(F$82="","",INDEX('Dữ liệu biểu đồ'!$C$49:$I$49,F$82-2019)) -> 23.156 | G86: =IF(G$82="","",INDEX('Dữ liệu biểu đồ'!$C$49:$I$49,G$82-2019)) -> 25.898 | H86: =IF(H$82="","",INDEX('Dữ liệu biểu đồ'!$C$49:$I$49,H$82-2019)) -> 25.608 | I86: =IF(I$82="","",INDEX('Dữ liệu biểu đồ'!$C$49:$I$49,I$82-2019)) -> 27.397 | J86: =IF(J$82="","",INDEX('Dữ liệu biểu đồ'!$C$49:$I$49,J$82-2019)) -> 27.758 | K86: =IF(K$82="","",INDEX('Dữ liệu biểu đồ'!$C$49:$I$49,K$82-2019)) -> 25.883 | L86: =IF(L$82="","",INDEX('Dữ liệu biểu đồ'!$C$49:$I$49,L$82-2019)) -> 27.453
F87: =IF(F$82="","",IF(INDEX('Dữ liệu biểu đồ'!$J$49:$P$49,F$82-2019)="",INDEX('Dữ liệu biểu đồ'!$C$50:$I$50,F$82-2019)&"",HYPERLINK(INDEX('Dữ liệu biểu đồ'!$J$49:$P$49,F$82-2019),INDEX('Dữ liệu biểu đồ'!$C$50:$I$50,F$82-2019)))) -> tr. 88 | G87: =IF(G$82="","",IF(INDEX('Dữ liệu biểu đồ'!$J$49:$P$49,G$82-2019)="",INDEX('Dữ liệu biểu đồ'!$C$50:$I$50,G$82-2019)&"",HYPERLINK(INDEX('Dữ liệu biểu đồ'!$J$49:$P$49,G$82-2019),INDEX('Dữ liệu biểu đồ'!$C$50:$I$50,G$82-2019)))) -> tr. 86 | H87: =IF(H$82="","",IF(INDEX('Dữ liệu biểu đồ'!$J$49:$P$49,H$82-2019)="",INDEX('Dữ liệu biểu đồ'!$C$50:$I$50,H$82-2019)&"",HYPERLINK(INDEX('Dữ liệu biểu đồ'!$J$49:$P$49,H$82-2019),INDEX('Dữ liệu biểu đồ'!$C$50:$I$50,H$82-2019)))) -> tr. 85 | I87: =IF(I$82="","",IF(INDEX('Dữ liệu biểu đồ'!$J$49:$P$49,I$82-2019)="",INDEX('Dữ liệu biểu đồ'!$C$50:$I$50,I$82-2019)&"",HYPERLINK(INDEX('Dữ liệu biểu đồ'!$J$49:$P$49,I$82-2019),INDEX('Dữ liệu biểu đồ'!$C$50:$I$50,I$82-2019)))) -> tr. 83 | J87: =IF(J$82="","",IF(INDEX('Dữ liệu biểu đồ'!$J$49:$P$49,J$82-2019)="",INDEX('Dữ liệu biểu đồ'!$C$50:$I$50,J$82-2019)&"",HYPERLINK(INDEX('Dữ liệu biểu đồ'!$J$49:$P$49,J$82-2019),INDEX('Dữ liệu biểu đồ'!$C$50:$I$50,J$82-2019)))) -> tr. 84 | K87: =IF(K$82="","",IF(INDEX('Dữ liệu biểu đồ'!$J$49:$P$49,K$82-2019)="",INDEX('Dữ liệu biểu đồ'!$C$50:$I$50,K$82-2019)&"",HYPERLINK(INDEX('Dữ liệu biểu đồ'!$J$49:$P$49,K$82-2019),INDEX('Dữ liệu biểu đồ'!$C$50:$I$50,K$82-2019)))) -> tr. 82 | L87: =IF(L$82="","",IF(INDEX('Dữ liệu biểu đồ'!$J$49:$P$49,L$82-2019)="",INDEX('Dữ liệu biểu đồ'!$C$50:$I$50,L$82-2019)&"",HYPERLINK(INDEX('Dữ liệu biểu đồ'!$J$49:$P$49,L$82-2019),INDEX('Dữ liệu biểu đồ'!$C$50:$I$50,L$82-2019)))) -> tr. 83
B88: Global Brand Divisions | E88: triệu USD | F88: =IF(F$82="","",INDEX('Dữ liệu biểu đồ'!$C$51:$I$51,F$82-2019)) -> 30 | G88: =IF(G$82="","",INDEX('Dữ liệu biểu đồ'!$C$51:$I$51,G$82-2019)) -> 25 | H88: =IF(H$82="","",INDEX('Dữ liệu biểu đồ'!$C$51:$I$51,H$82-2019)) -> 102 | I88: =IF(I$82="","",INDEX('Dữ liệu biểu đồ'!$C$51:$I$51,I$82-2019)) -> 58 | J88: =IF(J$82="","",INDEX('Dữ liệu biểu đồ'!$C$51:$I$51,J$82-2019)) -> 45 | K88: =IF(K$82="","",INDEX('Dữ liệu biểu đồ'!$C$51:$I$51,K$82-2019)) -> 48 | L88: =IF(L$82="","",INDEX('Dữ liệu biểu đồ'!$C$51:$I$51,L$82-2019)) -> 49
F89: =IF(F$82="","",IF(INDEX('Dữ liệu biểu đồ'!$J$51:$P$51,F$82-2019)="",INDEX('Dữ liệu biểu đồ'!$C$52:$I$52,F$82-2019)&"",HYPERLINK(INDEX('Dữ liệu biểu đồ'!$J$51:$P$51,F$82-2019),INDEX('Dữ liệu biểu đồ'!$C$52:$I$52,F$82-2019)))) -> tr. 88 | G89: =IF(G$82="","",IF(INDEX('Dữ liệu biểu đồ'!$J$51:$P$51,G$82-2019)="",INDEX('Dữ liệu biểu đồ'!$C$52:$I$52,G$82-2019)&"",HYPERLINK(INDEX('Dữ liệu biểu đồ'!$J$51:$P$51,G$82-2019),INDEX('Dữ liệu biểu đồ'!$C$52:$I$52,G$82-2019)))) -> tr. 86 | H89: =IF(H$82="","",IF(INDEX('Dữ liệu biểu đồ'!$J$51:$P$51,H$82-2019)="",INDEX('Dữ liệu biểu đồ'!$C$52:$I$52,H$82-2019)&"",HYPERLINK(INDEX('Dữ liệu biểu đồ'!$J$51:$P$51,H$82-2019),INDEX('Dữ liệu biểu đồ'!$C$52:$I$52,H$82-2019)))) -> tr. 85 | I89: =IF(I$82="","",IF(INDEX('Dữ liệu biểu đồ'!$J$51:$P$51,I$82-2019)="",INDEX('Dữ liệu biểu đồ'!$C$52:$I$52,I$82-2019)&"",HYPERLINK(INDEX('Dữ liệu biểu đồ'!$J$51:$P$51,I$82-2019),INDEX('Dữ liệu biểu đồ'!$C$52:$I$52,I$82-2019)))) -> tr. 83 | J89: =IF(J$82="","",IF(INDEX('Dữ liệu biểu đồ'!$J$51:$P$51,J$82-2019)="",INDEX('Dữ liệu biểu đồ'!$C$52:$I$52,J$82-2019)&"",HYPERLINK(INDEX('Dữ liệu biểu đồ'!$J$51:$P$51,J$82-2019),INDEX('Dữ liệu biểu đồ'!$C$52:$I$52,J$82-2019)))) -> tr. 84 | K89: =IF(K$82="","",IF(INDEX('Dữ liệu biểu đồ'!$J$51:$P$51,K$82-2019)="",INDEX('Dữ liệu biểu đồ'!$C$52:$I$52,K$82-2019)&"",HYPERLINK(INDEX('Dữ liệu biểu đồ'!$J$51:$P$51,K$82-2019),INDEX('Dữ liệu biểu đồ'!$C$52:$I$52,K$82-2019)))) -> tr. 82 | L89: =IF(L$82="","",IF(INDEX('Dữ liệu biểu đồ'!$J$51:$P$51,L$82-2019)="",INDEX('Dữ liệu biểu đồ'!$C$52:$I$52,L$82-2019)&"",HYPERLINK(INDEX('Dữ liệu biểu đồ'!$J$51:$P$51,L$82-2019),INDEX('Dữ liệu biểu đồ'!$C$52:$I$52,L$82-2019)))) -> tr. 83
B90: Tổng doanh thu NIKE Brand | E90: triệu USD | F90: =IF(F$82="","",INDEX('Dữ liệu biểu đồ'!$C$53:$I$53,F$82-2019)) -> 35.568 | G90: =IF(G$82="","",INDEX('Dữ liệu biểu đồ'!$C$53:$I$53,G$82-2019)) -> 42.293 | H90: =IF(H$82="","",INDEX('Dữ liệu biểu đồ'!$C$53:$I$53,H$82-2019)) -> 44.436 | I90: =IF(I$82="","",INDEX('Dữ liệu biểu đồ'!$C$53:$I$53,I$82-2019)) -> 48.763 | J90: =IF(J$82="","",INDEX('Dữ liệu biểu đồ'!$C$53:$I$53,J$82-2019)) -> 49.322 | K90: =IF(K$82="","",INDEX('Dữ liệu biểu đồ'!$C$53:$I$53,K$82-2019)) -> 44.714 | L90: =IF(L$82="","",INDEX('Dữ liệu biểu đồ'!$C$53:$I$53,L$82-2019)) -> 45.222
F91: =IF(F$82="","",IF(INDEX('Dữ liệu biểu đồ'!$J$53:$P$53,F$82-2019)="",INDEX('Dữ liệu biểu đồ'!$C$54:$I$54,F$82-2019)&"",HYPERLINK(INDEX('Dữ liệu biểu đồ'!$J$53:$P$53,F$82-2019),INDEX('Dữ liệu biểu đồ'!$C$54:$I$54,F$82-2019)))) -> tr. 88 | G91: =IF(G$82="","",IF(INDEX('Dữ liệu biểu đồ'!$J$53:$P$53,G$82-2019)="",INDEX('Dữ liệu biểu đồ'!$C$54:$I$54,G$82-2019)&"",HYPERLINK(INDEX('Dữ liệu biểu đồ'!$J$53:$P$53,G$82-2019),INDEX('Dữ liệu biểu đồ'!$C$54:$I$54,G$82-2019)))) -> tr. 86 | H91: =IF(H$82="","",IF(INDEX('Dữ liệu biểu đồ'!$J$53:$P$53,H$82-2019)="",INDEX('Dữ liệu biểu đồ'!$C$54:$I$54,H$82-2019)&"",HYPERLINK(INDEX('Dữ liệu biểu đồ'!$J$53:$P$53,H$82-2019),INDEX('Dữ liệu biểu đồ'!$C$54:$I$54,H$82-2019)))) -> tr. 85 | I91: =IF(I$82="","",IF(INDEX('Dữ liệu biểu đồ'!$J$53:$P$53,I$82-2019)="",INDEX('Dữ liệu biểu đồ'!$C$54:$I$54,I$82-2019)&"",HYPERLINK(INDEX('Dữ liệu biểu đồ'!$J$53:$P$53,I$82-2019),INDEX('Dữ liệu biểu đồ'!$C$54:$I$54,I$82-2019)))) -> tr. 83 | J91: =IF(J$82="","",IF(INDEX('Dữ liệu biểu đồ'!$J$53:$P$53,J$82-2019)="",INDEX('Dữ liệu biểu đồ'!$C$54:$I$54,J$82-2019)&"",HYPERLINK(INDEX('Dữ liệu biểu đồ'!$J$53:$P$53,J$82-2019),INDEX('Dữ liệu biểu đồ'!$C$54:$I$54,J$82-2019)))) -> tr. 84 | K91: =IF(K$82="","",IF(INDEX('Dữ liệu biểu đồ'!$J$53:$P$53,K$82-2019)="",INDEX('Dữ liệu biểu đồ'!$C$54:$I$54,K$82-2019)&"",HYPERLINK(INDEX('Dữ liệu biểu đồ'!$J$53:$P$53,K$82-2019),INDEX('Dữ liệu biểu đồ'!$C$54:$I$54,K$82-2019)))) -> tr. 82 | L91: =IF(L$82="","",IF(INDEX('Dữ liệu biểu đồ'!$J$53:$P$53,L$82-2019)="",INDEX('Dữ liệu biểu đồ'!$C$54:$I$54,L$82-2019)&"",HYPERLINK(INDEX('Dữ liệu biểu đồ'!$J$53:$P$53,L$82-2019),INDEX('Dữ liệu biểu đồ'!$C$54:$I$54,L$82-2019)))) -> tr. 83
B92: Cơ cấu theo kênh
B93: Tỷ trọng NIKE Direct | E93: % | F93: =IF(F$82="","",INDEX('Dữ liệu biểu đồ'!$C$55:$I$55,F$82-2019)) -> 34,8% | G93: =IF(G$82="","",INDEX('Dữ liệu biểu đồ'!$C$55:$I$55,G$82-2019)) -> 38,7% | H93: =IF(H$82="","",INDEX('Dữ liệu biểu đồ'!$C$55:$I$55,H$82-2019)) -> 42,1% | I93: =IF(I$82="","",INDEX('Dữ liệu biểu đồ'!$C$55:$I$55,I$82-2019)) -> 43,7% | J93: =IF(J$82="","",INDEX('Dữ liệu biểu đồ'!$C$55:$I$55,J$82-2019)) -> 43,6% | K93: =IF(K$82="","",INDEX('Dữ liệu biểu đồ'!$C$55:$I$55,K$82-2019)) -> 42,0% | L93: =IF(L$82="","",INDEX('Dữ liệu biểu đồ'!$C$55:$I$55,L$82-2019)) -> 39,2%
B94: Tỷ trọng bán buôn | E94: % | F94: =IF(F$82="","",INDEX('Dữ liệu biểu đồ'!$C$57:$I$57,F$82-2019)) -> 65,1% | G94: =IF(G$82="","",INDEX('Dữ liệu biểu đồ'!$C$57:$I$57,G$82-2019)) -> 61,2% | H94: =IF(H$82="","",INDEX('Dữ liệu biểu đồ'!$C$57:$I$57,H$82-2019)) -> 57,6% | I94: =IF(I$82="","",INDEX('Dữ liệu biểu đồ'!$C$57:$I$57,I$82-2019)) -> 56,2% | J94: =IF(J$82="","",INDEX('Dữ liệu biểu đồ'!$C$57:$I$57,J$82-2019)) -> 56,3% | K94: =IF(K$82="","",INDEX('Dữ liệu biểu đồ'!$C$57:$I$57,K$82-2019)) -> 57,9% | L94: =IF(L$82="","",INDEX('Dữ liệu biểu đồ'!$C$57:$I$57,L$82-2019)) -> 60,7%
B95: Tỷ trọng NIKE Direct do NIKE nêu (xấp xỉ) | E95: % | F95: =IF(F$82="","",INDEX('Dữ liệu biểu đồ'!$C$59:$I$59,F$82-2019)) -> 35% | G95: =IF(G$82="","",INDEX('Dữ liệu biểu đồ'!$C$59:$I$59,G$82-2019)) -> 39% | H95: =IF(H$82="","",INDEX('Dữ liệu biểu đồ'!$C$59:$I$59,H$82-2019)) -> 42% | I95: =IF(I$82="","",INDEX('Dữ liệu biểu đồ'!$C$59:$I$59,I$82-2019)) -> 44% | J95: =IF(J$82="","",INDEX('Dữ liệu biểu đồ'!$C$59:$I$59,J$82-2019)) -> 44% | K95: =IF(K$82="","",INDEX('Dữ liệu biểu đồ'!$C$59:$I$59,K$82-2019)) -> 42% | L95: =IF(L$82="","",INDEX('Dữ liệu biểu đồ'!$C$59:$I$59,L$82-2019)) -> Không công bố
F96: =IF(F$82="","",IF(INDEX('Dữ liệu biểu đồ'!$J$59:$P$59,F$82-2019)="",INDEX('Dữ liệu biểu đồ'!$C$60:$I$60,F$82-2019)&"",HYPERLINK(INDEX('Dữ liệu biểu đồ'!$J$59:$P$59,F$82-2019),INDEX('Dữ liệu biểu đồ'!$C$60:$I$60,F$82-2019)))) -> tr. 32 | G96: =IF(G$82="","",IF(INDEX('Dữ liệu biểu đồ'!$J$59:$P$59,G$82-2019)="",INDEX('Dữ liệu biểu đồ'!$C$60:$I$60,G$82-2019)&"",HYPERLINK(INDEX('Dữ liệu biểu đồ'!$J$59:$P$59,G$82-2019),INDEX('Dữ liệu biểu đồ'!$C$60:$I$60,G$82-2019)))) -> tr. 33 | H96: =IF(H$82="","",IF(INDEX('Dữ liệu biểu đồ'!$J$59:$P$59,H$82-2019)="",INDEX('Dữ liệu biểu đồ'!$C$60:$I$60,H$82-2019)&"",HYPERLINK(INDEX('Dữ liệu biểu đồ'!$J$59:$P$59,H$82-2019),INDEX('Dữ liệu biểu đồ'!$C$60:$I$60,H$82-2019)))) -> tr. 28 | I96: =IF(I$82="","",IF(INDEX('Dữ liệu biểu đồ'!$J$59:$P$59,I$82-2019)="",INDEX('Dữ liệu biểu đồ'!$C$60:$I$60,I$82-2019)&"",HYPERLINK(INDEX('Dữ liệu biểu đồ'!$J$59:$P$59,I$82-2019),INDEX('Dữ liệu biểu đồ'!$C$60:$I$60,I$82-2019)))) -> tr. 28 | J96: =IF(J$82="","",IF(INDEX('Dữ liệu biểu đồ'!$J$59:$P$59,J$82-2019)="",INDEX('Dữ liệu biểu đồ'!$C$60:$I$60,J$82-2019)&"",HYPERLINK(INDEX('Dữ liệu biểu đồ'!$J$59:$P$59,J$82-2019),INDEX('Dữ liệu biểu đồ'!$C$60:$I$60,J$82-2019)))) -> tr. 30 | K96: =IF(K$82="","",IF(INDEX('Dữ liệu biểu đồ'!$J$59:$P$59,K$82-2019)="",INDEX('Dữ liệu biểu đồ'!$C$60:$I$60,K$82-2019)&"",HYPERLINK(INDEX('Dữ liệu biểu đồ'!$J$59:$P$59,K$82-2019),INDEX('Dữ liệu biểu đồ'!$C$60:$I$60,K$82-2019)))) -> tr. 29 | L96: =IF(L$82="","",IF(INDEX('Dữ liệu biểu đồ'!$J$59:$P$59,L$82-2019)="",INDEX('Dữ liệu biểu đồ'!$C$60:$I$60,L$82-2019)&"",HYPERLINK(INDEX('Dữ liệu biểu đồ'!$J$59:$P$59,L$82-2019),INDEX('Dữ liệu biểu đồ'!$C$60:$I$60,L$82-2019))))
B97: Tăng trưởng so với năm trước
B98: NIKE Direct, theo báo cáo | E98: % | F98: =IF(F$82="","",INDEX('Dữ liệu biểu đồ'!$C$61:$I$61,F$82-2019)) -> +5,4% | G98: =IF(G$82="","",INDEX('Dữ liệu biểu đồ'!$C$61:$I$61,G$82-2019)) -> +32,2% | H98: =IF(H$82="","",INDEX('Dữ liệu biểu đồ'!$C$61:$I$61,H$82-2019)) -> +14,4% | I98: =IF(I$82="","",INDEX('Dữ liệu biểu đồ'!$C$61:$I$61,I$82-2019)) -> +13,8% | J98: =IF(J$82="","",INDEX('Dữ liệu biểu đồ'!$C$61:$I$61,J$82-2019)) -> +1,0% | K98: =IF(K$82="","",INDEX('Dữ liệu biểu đồ'!$C$61:$I$61,K$82-2019)) -> −12,7% | L98: =IF(L$82="","",INDEX('Dữ liệu biểu đồ'!$C$61:$I$61,L$82-2019)) -> −5,7%
B99: NIKE Direct, loại trừ tỷ giá (non‑GAAP) | E99: % | F99: =IF(F$82="","",INDEX('Dữ liệu biểu đồ'!$C$63:$I$63,F$82-2019)) -> +8% | G99: =IF(G$82="","",INDEX('Dữ liệu biểu đồ'!$C$63:$I$63,G$82-2019)) -> +30% | H99: =IF(H$82="","",INDEX('Dữ liệu biểu đồ'!$C$63:$I$63,H$82-2019)) -> +15% | I99: =IF(I$82="","",INDEX('Dữ liệu biểu đồ'!$C$63:$I$63,I$82-2019)) -> +20% | J99: =IF(J$82="","",INDEX('Dữ liệu biểu đồ'!$C$63:$I$63,J$82-2019)) -> +1% | K99: =IF(K$82="","",INDEX('Dữ liệu biểu đồ'!$C$63:$I$63,K$82-2019)) -> −12% | L99: =IF(L$82="","",INDEX('Dữ liệu biểu đồ'!$C$63:$I$63,L$82-2019)) -> −8%
F100: =IF(F$82="","",IF(INDEX('Dữ liệu biểu đồ'!$J$63:$P$63,F$82-2019)="",INDEX('Dữ liệu biểu đồ'!$C$64:$I$64,F$82-2019)&"",HYPERLINK(INDEX('Dữ liệu biểu đồ'!$J$63:$P$63,F$82-2019),INDEX('Dữ liệu biểu đồ'!$C$64:$I$64,F$82-2019)))) -> tr. 31 | G100: =IF(G$82="","",IF(INDEX('Dữ liệu biểu đồ'!$J$63:$P$63,G$82-2019)="",INDEX('Dữ liệu biểu đồ'!$C$64:$I$64,G$82-2019)&"",HYPERLINK(INDEX('Dữ liệu biểu đồ'!$J$63:$P$63,G$82-2019),INDEX('Dữ liệu biểu đồ'!$C$64:$I$64,G$82-2019)))) -> tr. 32 | H100: =IF(H$82="","",IF(INDEX('Dữ liệu biểu đồ'!$J$63:$P$63,H$82-2019)="",INDEX('Dữ liệu biểu đồ'!$C$64:$I$64,H$82-2019)&"",HYPERLINK(INDEX('Dữ liệu biểu đồ'!$J$63:$P$63,H$82-2019),INDEX('Dữ liệu biểu đồ'!$C$64:$I$64,H$82-2019)))) -> tr. 32 | I100: =IF(I$82="","",IF(INDEX('Dữ liệu biểu đồ'!$J$63:$P$63,I$82-2019)="",INDEX('Dữ liệu biểu đồ'!$C$64:$I$64,I$82-2019)&"",HYPERLINK(INDEX('Dữ liệu biểu đồ'!$J$63:$P$63,I$82-2019),INDEX('Dữ liệu biểu đồ'!$C$64:$I$64,I$82-2019)))) -> tr. 32 | J100: =IF(J$82="","",IF(INDEX('Dữ liệu biểu đồ'!$J$63:$P$63,J$82-2019)="",INDEX('Dữ liệu biểu đồ'!$C$64:$I$64,J$82-2019)&"",HYPERLINK(INDEX('Dữ liệu biểu đồ'!$J$63:$P$63,J$82-2019),INDEX('Dữ liệu biểu đồ'!$C$64:$I$64,J$82-2019)))) -> tr. 34 | K100: =IF(K$82="","",IF(INDEX('Dữ liệu biểu đồ'!$J$63:$P$63,K$82-2019)="",INDEX('Dữ liệu biểu đồ'!$C$64:$I$64,K$82-2019)&"",HYPERLINK(INDEX('Dữ liệu biểu đồ'!$J$63:$P$63,K$82-2019),INDEX('Dữ liệu biểu đồ'!$C$64:$I$64,K$82-2019)))) -> tr. 33 | L100: =IF(L$82="","",IF(INDEX('Dữ liệu biểu đồ'!$J$63:$P$63,L$82-2019)="",INDEX('Dữ liệu biểu đồ'!$C$64:$I$64,L$82-2019)&"",HYPERLINK(INDEX('Dữ liệu biểu đồ'!$J$63:$P$63,L$82-2019),INDEX('Dữ liệu biểu đồ'!$C$64:$I$64,L$82-2019)))) -> tr. 32
B101: Bán buôn, theo báo cáo | E101: % | F101: =IF(F$82="","",INDEX('Dữ liệu biểu đồ'!$C$65:$I$65,F$82-2019)) -> −8,9% | G101: =IF(G$82="","",INDEX('Dữ liệu biểu đồ'!$C$65:$I$65,G$82-2019)) -> +11,8% | H101: =IF(H$82="","",INDEX('Dữ liệu biểu đồ'!$C$65:$I$65,H$82-2019)) -> −1,1% | I101: =IF(I$82="","",INDEX('Dữ liệu biểu đồ'!$C$65:$I$65,I$82-2019)) -> +7,0% | J101: =IF(J$82="","",INDEX('Dữ liệu biểu đồ'!$C$65:$I$65,J$82-2019)) -> +1,3% | K101: =IF(K$82="","",INDEX('Dữ liệu biểu đồ'!$C$65:$I$65,K$82-2019)) -> −6,8% | L101: =IF(L$82="","",INDEX('Dữ liệu biểu đồ'!$C$65:$I$65,L$82-2019)) -> +6,1%
B102: Bán buôn, loại trừ tỷ giá (non‑GAAP) | E102: % | F102: =IF(F$82="","",INDEX('Dữ liệu biểu đồ'!$C$67:$I$67,F$82-2019)) -> −7% | G102: =IF(G$82="","",INDEX('Dữ liệu biểu đồ'!$C$67:$I$67,G$82-2019)) -> +10% | H102: =IF(H$82="","",INDEX('Dữ liệu biểu đồ'!$C$67:$I$67,H$82-2019)) -> −1% | I102: =IF(I$82="","",INDEX('Dữ liệu biểu đồ'!$C$67:$I$67,I$82-2019)) -> +14% | J102: =IF(J$82="","",INDEX('Dữ liệu biểu đồ'!$C$67:$I$67,J$82-2019)) -> +2% | K102: =IF(K$82="","",INDEX('Dữ liệu biểu đồ'!$C$67:$I$67,K$82-2019)) -> −6% | L102: =IF(L$82="","",INDEX('Dữ liệu biểu đồ'!$C$67:$I$67,L$82-2019)) -> +4%
F103: =IF(F$82="","",IF(INDEX('Dữ liệu biểu đồ'!$J$67:$P$67,F$82-2019)="",INDEX('Dữ liệu biểu đồ'!$C$68:$I$68,F$82-2019)&"",HYPERLINK(INDEX('Dữ liệu biểu đồ'!$J$67:$P$67,F$82-2019),INDEX('Dữ liệu biểu đồ'!$C$68:$I$68,F$82-2019)))) -> tr. 31 | G103: =IF(G$82="","",IF(INDEX('Dữ liệu biểu đồ'!$J$67:$P$67,G$82-2019)="",INDEX('Dữ liệu biểu đồ'!$C$68:$I$68,G$82-2019)&"",HYPERLINK(INDEX('Dữ liệu biểu đồ'!$J$67:$P$67,G$82-2019),INDEX('Dữ liệu biểu đồ'!$C$68:$I$68,G$82-2019)))) -> tr. 32 | H103: =IF(H$82="","",IF(INDEX('Dữ liệu biểu đồ'!$J$67:$P$67,H$82-2019)="",INDEX('Dữ liệu biểu đồ'!$C$68:$I$68,H$82-2019)&"",HYPERLINK(INDEX('Dữ liệu biểu đồ'!$J$67:$P$67,H$82-2019),INDEX('Dữ liệu biểu đồ'!$C$68:$I$68,H$82-2019)))) -> tr. 32 | I103: =IF(I$82="","",IF(INDEX('Dữ liệu biểu đồ'!$J$67:$P$67,I$82-2019)="",INDEX('Dữ liệu biểu đồ'!$C$68:$I$68,I$82-2019)&"",HYPERLINK(INDEX('Dữ liệu biểu đồ'!$J$67:$P$67,I$82-2019),INDEX('Dữ liệu biểu đồ'!$C$68:$I$68,I$82-2019)))) -> tr. 32 | J103: =IF(J$82="","",IF(INDEX('Dữ liệu biểu đồ'!$J$67:$P$67,J$82-2019)="",INDEX('Dữ liệu biểu đồ'!$C$68:$I$68,J$82-2019)&"",HYPERLINK(INDEX('Dữ liệu biểu đồ'!$J$67:$P$67,J$82-2019),INDEX('Dữ liệu biểu đồ'!$C$68:$I$68,J$82-2019)))) -> tr. 34 | K103: =IF(K$82="","",IF(INDEX('Dữ liệu biểu đồ'!$J$67:$P$67,K$82-2019)="",INDEX('Dữ liệu biểu đồ'!$C$68:$I$68,K$82-2019)&"",HYPERLINK(INDEX('Dữ liệu biểu đồ'!$J$67:$P$67,K$82-2019),INDEX('Dữ liệu biểu đồ'!$C$68:$I$68,K$82-2019)))) -> tr. 33 | L103: =IF(L$82="","",IF(INDEX('Dữ liệu biểu đồ'!$J$67:$P$67,L$82-2019)="",INDEX('Dữ liệu biểu đồ'!$C$68:$I$68,L$82-2019)&"",HYPERLINK(INDEX('Dữ liệu biểu đồ'!$J$67:$P$67,L$82-2019),INDEX('Dữ liệu biểu đồ'!$C$68:$I$68,L$82-2019)))) -> tr. 32
...

Sheet Kết quả tài chính
B2: Phân phối và kết quả tài chính của NIKE, FY2020–FY2026 | M2: Tải bộ dữ liệu Excel
B3: Số liệu lấy từ báo cáo thường niên Form 10‑K mà NIKE, Inc. nộp cho Ủy ban Chứng khoán Mỹ (SEC). Năm tài chính của NIKE kết thúc ngày 31/5. | M3: Nguồn và phương pháp
M4: Mở dashboard web
B6: Chiến lược phân phối | D6: Kết quả tài chính
J8: Bấm một năm để lọc, giữ Ctrl để chọn nhiều năm. Bấm nút xóa lọc ở góc slicer để xem lại đủ 7 năm.
B12: Kết quả tài chính hợp nhất của NIKE biến động ra sao trong cùng giai đoạn? | I12: Tóm tắt theo khoảng năm đang chọn
I13: ='Dữ liệu biểu đồ'!$C$28 -> Doanh thu NIKE, Inc. đi từ 37,4 (FY2020) đến 46,4 tỷ USD (FY2026). Biên lợi nhuận gộp là 43,4% (FY2020) và 42,9% (FY2026), còn biên EBIT (non‑GAAP) là 8,0% (FY2020) và 8,3% (FY2026), cao nhất 15,5% (FY2021). Hàng tồn kho cuối kỳ đi từ 7,4 đến 7,5 tỷ USD.
B19: Doanh thu | F19: Biên lợi nhuận gộp | J19: Chi phí bán hàng và quản lý
B20: Tỷ USD, NIKE, Inc. | F20: % doanh thu, NIKE, Inc. Trục tung không bắt đầu từ 0. | J20: % doanh thu, NIKE, Inc. Hai phần cộng lại bằng tổng SG&A.
B34: ="Nguồn: Consolidated Statements of Income."&'Dữ liệu biểu đồ'!$C$31 -> Nguồn: Consolidated Statements of Income. Báo cáo: 10‑K FY2020–FY2026 (danh sách ở sheet “Nguồn và phương pháp”). | F34: ="Nguồn: Consolidated Statements of Income. Biên lợi nhuận gộp do nhóm tự tính."&'Dữ liệu biểu đồ'!$C$31 -> Nguồn: Consolidated Statements of Income. Biên lợi nhuận gộp do nhóm tự tính. Báo cáo: 10‑K FY2020–FY2026 (danh sách ở sheet “Nguồn và phương pháp”). | J34: ="Nguồn: Consolidated Statements of Income. Tỷ lệ do nhóm tự tính. Nhãn trên cột là tổng SG&A / doanh thu."&'Dữ liệu biểu đồ'!$C$31 -> Nguồn: Consolidated Statements of Income. Tỷ lệ do nhóm tự tính. Nhãn trên cột là tổng SG&A / doanh thu. Báo cáo: 10‑K FY2020–FY2026 (danh sách ở sheet “Nguồn và phương pháp”).
B36: Biên EBIT (non‑GAAP) | F36: Hàng tồn kho cuối kỳ | J36: Số ngày tồn kho bình quân
B37: % doanh thu, NIKE, Inc. | F37: Tỷ USD, số dư tại 31/5, NIKE, Inc. | J37: Ngày. Trục tung không bắt đầu từ 0.
B51: ="Nguồn: bảng EBIT trong MD&A (Item 7) và Consolidated Statements of Income. Biên EBIT do nhóm tự tính."&'Dữ liệu biểu đồ'!$C$31 -> Nguồn: bảng EBIT trong MD&A (Item 7) và Consolidated Statements of Income. Biên EBIT do nhóm tự tính. Báo cáo: 10‑K FY2020–FY2026 (danh sách ở sheet “Nguồn và phương pháp”). | F51: ="Nguồn: Consolidated Balance Sheets."&'Dữ liệu biểu đồ'!$C$31 -> Nguồn: Consolidated Balance Sheets. Báo cáo: 10‑K FY2020–FY2026 (danh sách ở sheet “Nguồn và phương pháp”). | J51: ="Nguồn: Consolidated Balance Sheets và Statements of Income. Chỉ số do nhóm tự tính."&'Dữ liệu biểu đồ'!$C$31 -> Nguồn: Consolidated Balance Sheets và Statements of Income. Chỉ số do nhóm tự tính. Báo cáo: 10‑K FY2020–FY2026 (danh sách ở sheet “Nguồn và phương pháp”).
B53: Lưu ý kế toán
B54: Không có dòng “operating income” Báo cáo kết quả kinh doanh của NIKE không có dòng tổng phụ này: ngay sau tổng chi phí bán hàng và quản lý là chi phí (thu nhập) lãi thuần, chi phí (thu nhập) khác thuần, rồi đến lợi nhuận trước thuế. EBIT (lợi nhuận sau thuế + chi phí lãi thuần + thuế) là chỉ tiêu non‑GAAP do NIKE tự định nghĩa, và vẫn bao gồm khoản chi phí (thu nhập) khác thuần. | F54: Chi phí là số hợp nhất SG&A không được NIKE phân bổ cho NIKE Direct hay bán buôn, nên các tỷ lệ chi phí và biên lợi nhuận ở đây là của toàn NIKE, Inc. | J54: Số dư và số phát sinh Hàng tồn kho là số dư tại 31/5. Số ngày tồn kho = 365 × hàng tồn kho bình quân đầu và cuối kỳ / giá vốn hàng bán.
B59: Bảng số liệu kết quả tài chính (NIKE, Inc.)
B60: Đơn vị triệu USD, trừ khi ghi khác. Số âm để trong ngoặc đơn. Số NIKE công bố có số trang 10‑K ở dòng nhỏ ngay dưới (bấm vào số trang để mở báo cáo trên SEC). Số in nghiêng là số nhóm tự tính.
B61: Chỉ tiêu | E61: Đơn vị | F61: =IFERROR(_xlfn.AGGREGATE(15,5,'Dữ liệu biểu đồ'!$B$5:$B$11,1),"") -> 2020 | G61: =IFERROR(_xlfn.AGGREGATE(15,5,'Dữ liệu biểu đồ'!$B$5:$B$11,2),"") -> 2021 | H61: =IFERROR(_xlfn.AGGREGATE(15,5,'Dữ liệu biểu đồ'!$B$5:$B$11,3),"") -> 2022 | I61: =IFERROR(_xlfn.AGGREGATE(15,5,'Dữ liệu biểu đồ'!$B$5:$B$11,4),"") -> 2023 | J61: =IFERROR(_xlfn.AGGREGATE(15,5,'Dữ liệu biểu đồ'!$B$5:$B$11,5),"") -> 2024 | K61: =IFERROR(_xlfn.AGGREGATE(15,5,'Dữ liệu biểu đồ'!$B$5:$B$11,6),"") -> 2025 | L61: =IFERROR(_xlfn.AGGREGATE(15,5,'Dữ liệu biểu đồ'!$B$5:$B$11,7),"") -> 2026
B62: Báo cáo kết quả kinh doanh
B63: Doanh thu | E63: triệu USD | F63: =IF(F$61="","",INDEX('Dữ liệu biểu đồ'!$C$75:$I$75,F$61-2019)) -> 37.403 | G63: =IF(G$61="","",INDEX('Dữ liệu biểu đồ'!$C$75:$I$75,G$61-2019)) -> 44.538 | H63: =IF(H$61="","",INDEX('Dữ liệu biểu đồ'!$C$75:$I$75,H$61-2019)) -> 46.710 | I63: =IF(I$61="","",INDEX('Dữ liệu biểu đồ'!$C$75:$I$75,I$61-2019)) -> 51.217 | J63: =IF(J$61="","",INDEX('Dữ liệu biểu đồ'!$C$75:$I$75,J$61-2019)) -> 51.362 | K63: =IF(K$61="","",INDEX('Dữ liệu biểu đồ'!$C$75:$I$75,K$61-2019)) -> 46.309 | L63: =IF(L$61="","",INDEX('Dữ liệu biểu đồ'!$C$75:$I$75,L$61-2019)) -> 46.398
F64: =IF(F$61="","",IF(INDEX('Dữ liệu biểu đồ'!$J$75:$P$75,F$61-2019)="",INDEX('Dữ liệu biểu đồ'!$C$76:$I$76,F$61-2019)&"",HYPERLINK(INDEX('Dữ liệu biểu đồ'!$J$75:$P$75,F$61-2019),INDEX('Dữ liệu biểu đồ'!$C$76:$I$76,F$61-2019)))) -> tr. 56 | G64: =IF(G$61="","",IF(INDEX('Dữ liệu biểu đồ'!$J$75:$P$75,G$61-2019)="",INDEX('Dữ liệu biểu đồ'!$C$76:$I$76,G$61-2019)&"",HYPERLINK(INDEX('Dữ liệu biểu đồ'!$J$75:$P$75,G$61-2019),INDEX('Dữ liệu biểu đồ'!$C$76:$I$76,G$61-2019)))) -> tr. 57 | H64: =IF(H$61="","",IF(INDEX('Dữ liệu biểu đồ'!$J$75:$P$75,H$61-2019)="",INDEX('Dữ liệu biểu đồ'!$C$76:$I$76,H$61-2019)&"",HYPERLINK(INDEX('Dữ liệu biểu đồ'!$J$75:$P$75,H$61-2019),INDEX('Dữ liệu biểu đồ'!$C$76:$I$76,H$61-2019)))) -> tr. 56 | I64: =IF(I$61="","",IF(INDEX('Dữ liệu biểu đồ'!$J$75:$P$75,I$61-2019)="",INDEX('Dữ liệu biểu đồ'!$C$76:$I$76,I$61-2019)&"",HYPERLINK(INDEX('Dữ liệu biểu đồ'!$J$75:$P$75,I$61-2019),INDEX('Dữ liệu biểu đồ'!$C$76:$I$76,I$61-2019)))) -> tr. 55 | J64: =IF(J$61="","",IF(INDEX('Dữ liệu biểu đồ'!$J$75:$P$75,J$61-2019)="",INDEX('Dữ liệu biểu đồ'!$C$76:$I$76,J$61-2019)&"",HYPERLINK(INDEX('Dữ liệu biểu đồ'!$J$75:$P$75,J$61-2019),INDEX('Dữ liệu biểu đồ'!$C$76:$I$76,J$61-2019)))) -> tr. 57 | K64: =IF(K$61="","",IF(INDEX('Dữ liệu biểu đồ'!$J$75:$P$75,K$61-2019)="",INDEX('Dữ liệu biểu đồ'!$C$76:$I$76,K$61-2019)&"",HYPERLINK(INDEX('Dữ liệu biểu đồ'!$J$75:$P$75,K$61-2019),INDEX('Dữ liệu biểu đồ'!$C$76:$I$76,K$61-2019)))) -> tr. 56 | L64: =IF(L$61="","",IF(INDEX('Dữ liệu biểu đồ'!$J$75:$P$75,L$61-2019)="",INDEX('Dữ liệu biểu đồ'!$C$76:$I$76,L$61-2019)&"",HYPERLINK(INDEX('Dữ liệu biểu đồ'!$J$75:$P$75,L$61-2019),INDEX('Dữ liệu biểu đồ'!$C$76:$I$76,L$61-2019)))) -> tr. 55
B65: Giá vốn hàng bán | E65: triệu USD | F65: =IF(F$61="","",INDEX('Dữ liệu biểu đồ'!$C$77:$I$77,F$61-2019)) -> 21.162 | G65: =IF(G$61="","",INDEX('Dữ liệu biểu đồ'!$C$77:$I$77,G$61-2019)) -> 24.576 | H65: =IF(H$61="","",INDEX('Dữ liệu biểu đồ'!$C$77:$I$77,H$61-2019)) -> 25.231 | I65: =IF(I$61="","",INDEX('Dữ liệu biểu đồ'!$C$77:$I$77,I$61-2019)) -> 28.925 | J65: =IF(J$61="","",INDEX('Dữ liệu biểu đồ'!$C$77:$I$77,J$61-2019)) -> 28.475 | K65: =IF(K$61="","",INDEX('Dữ liệu biểu đồ'!$C$77:$I$77,K$61-2019)) -> 26.519 | L65: =IF(L$61="","",INDEX('Dữ liệu biểu đồ'!$C$77:$I$77,L$61-2019)) -> 26.487
F66: =IF(F$61="","",IF(INDEX('Dữ liệu biểu đồ'!$J$77:$P$77,F$61-2019)="",INDEX('Dữ liệu biểu đồ'!$C$78:$I$78,F$61-2019)&"",HYPERLINK(INDEX('Dữ liệu biểu đồ'!$J$77:$P$77,F$61-2019),INDEX('Dữ liệu biểu đồ'!$C$78:$I$78,F$61-2019)))) -> tr. 56 | G66: =IF(G$61="","",IF(INDEX('Dữ liệu biểu đồ'!$J$77:$P$77,G$61-2019)="",INDEX('Dữ liệu biểu đồ'!$C$78:$I$78,G$61-2019)&"",HYPERLINK(INDEX('Dữ liệu biểu đồ'!$J$77:$P$77,G$61-2019),INDEX('Dữ liệu biểu đồ'!$C$78:$I$78,G$61-2019)))) -> tr. 57 | H66: =IF(H$61="","",IF(INDEX('Dữ liệu biểu đồ'!$J$77:$P$77,H$61-2019)="",INDEX('Dữ liệu biểu đồ'!$C$78:$I$78,H$61-2019)&"",HYPERLINK(INDEX('Dữ liệu biểu đồ'!$J$77:$P$77,H$61-2019),INDEX('Dữ liệu biểu đồ'!$C$78:$I$78,H$61-2019)))) -> tr. 56 | I66: =IF(I$61="","",IF(INDEX('Dữ liệu biểu đồ'!$J$77:$P$77,I$61-2019)="",INDEX('Dữ liệu biểu đồ'!$C$78:$I$78,I$61-2019)&"",HYPERLINK(INDEX('Dữ liệu biểu đồ'!$J$77:$P$77,I$61-2019),INDEX('Dữ liệu biểu đồ'!$C$78:$I$78,I$61-2019)))) -> tr. 55 | J66: =IF(J$61="","",IF(INDEX('Dữ liệu biểu đồ'!$J$77:$P$77,J$61-2019)="",INDEX('Dữ liệu biểu đồ'!$C$78:$I$78,J$61-2019)&"",HYPERLINK(INDEX('Dữ liệu biểu đồ'!$J$77:$P$77,J$61-2019),INDEX('Dữ liệu biểu đồ'!$C$78:$I$78,J$61-2019)))) -> tr. 57 | K66: =IF(K$61="","",IF(INDEX('Dữ liệu biểu đồ'!$J$77:$P$77,K$61-2019)="",INDEX('Dữ liệu biểu đồ'!$C$78:$I$78,K$61-2019)&"",HYPERLINK(INDEX('Dữ liệu biểu đồ'!$J$77:$P$77,K$61-2019),INDEX('Dữ liệu biểu đồ'!$C$78:$I$78,K$61-2019)))) -> tr. 56 | L66: =IF(L$61="","",IF(INDEX('Dữ liệu biểu đồ'!$J$77:$P$77,L$61-2019)="",INDEX('Dữ liệu biểu đồ'!$C$78:$I$78,L$61-2019)&"",HYPERLINK(INDEX('Dữ liệu biểu đồ'!$J$77:$P$77,L$61-2019),INDEX('Dữ liệu biểu đồ'!$C$78:$I$78,L$61-2019)))) -> tr. 55
B67: Lợi nhuận gộp | E67: triệu USD | F67: =IF(F$61="","",INDEX('Dữ liệu biểu đồ'!$C$79:$I$79,F$61-2019)) -> 16.241 | G67: =IF(G$61="","",INDEX('Dữ liệu biểu đồ'!$C$79:$I$79,G$61-2019)) -> 19.962 | H67: =IF(H$61="","",INDEX('Dữ liệu biểu đồ'!$C$79:$I$79,H$61-2019)) -> 21.479 | I67: =IF(I$61="","",INDEX('Dữ liệu biểu đồ'!$C$79:$I$79,I$61-2019)) -> 22.292 | J67: =IF(J$61="","",INDEX('Dữ liệu biểu đồ'!$C$79:$I$79,J$61-2019)) -> 22.887 | K67: =IF(K$61="","",INDEX('Dữ liệu biểu đồ'!$C$79:$I$79,K$61-2019)) -> 19.790 | L67: =IF(L$61="","",INDEX('Dữ liệu biểu đồ'!$C$79:$I$79,L$61-2019)) -> 19.911
F68: =IF(F$61="","",IF(INDEX('Dữ liệu biểu đồ'!$J$79:$P$79,F$61-2019)="",INDEX('Dữ liệu biểu đồ'!$C$80:$I$80,F$61-2019)&"",HYPERLINK(INDEX('Dữ liệu biểu đồ'!$J$79:$P$79,F$61-2019),INDEX('Dữ liệu biểu đồ'!$C$80:$I$80,F$61-2019)))) -> tr. 56 | G68: =IF(G$61="","",IF(INDEX('Dữ liệu biểu đồ'!$J$79:$P$79,G$61-2019)="",INDEX('Dữ liệu biểu đồ'!$C$80:$I$80,G$61-2019)&"",HYPERLINK(INDEX('Dữ liệu biểu đồ'!$J$79:$P$79,G$61-2019),INDEX('Dữ liệu biểu đồ'!$C$80:$I$80,G$61-2019)))) -> tr. 57 | H68: =IF(H$61="","",IF(INDEX('Dữ liệu biểu đồ'!$J$79:$P$79,H$61-2019)="",INDEX('Dữ liệu biểu đồ'!$C$80:$I$80,H$61-2019)&"",HYPERLINK(INDEX('Dữ liệu biểu đồ'!$J$79:$P$79,H$61-2019),INDEX('Dữ liệu biểu đồ'!$C$80:$I$80,H$61-2019)))) -> tr. 56 | I68: =IF(I$61="","",IF(INDEX('Dữ liệu biểu đồ'!$J$79:$P$79,I$61-2019)="",INDEX('Dữ liệu biểu đồ'!$C$80:$I$80,I$61-2019)&"",HYPERLINK(INDEX('Dữ liệu biểu đồ'!$J$79:$P$79,I$61-2019),INDEX('Dữ liệu biểu đồ'!$C$80:$I$80,I$61-2019)))) -> tr. 55 | J68: =IF(J$61="","",IF(INDEX('Dữ liệu biểu đồ'!$J$79:$P$79,J$61-2019)="",INDEX('Dữ liệu biểu đồ'!$C$80:$I$80,J$61-2019)&"",HYPERLINK(INDEX('Dữ liệu biểu đồ'!$J$79:$P$79,J$61-2019),INDEX('Dữ liệu biểu đồ'!$C$80:$I$80,J$61-2019)))) -> tr. 57 | K68: =IF(K$61="","",IF(INDEX('Dữ liệu biểu đồ'!$J$79:$P$79,K$61-2019)="",INDEX('Dữ liệu biểu đồ'!$C$80:$I$80,K$61-2019)&"",HYPERLINK(INDEX('Dữ liệu biểu đồ'!$J$79:$P$79,K$61-2019),INDEX('Dữ liệu biểu đồ'!$C$80:$I$80,K$61-2019)))) -> tr. 56 | L68: =IF(L$61="","",IF(INDEX('Dữ liệu biểu đồ'!$J$79:$P$79,L$61-2019)="",INDEX('Dữ liệu biểu đồ'!$C$80:$I$80,L$61-2019)&"",HYPERLINK(INDEX('Dữ liệu biểu đồ'!$J$79:$P$79,L$61-2019),INDEX('Dữ liệu biểu đồ'!$C$80:$I$80,L$61-2019)))) -> tr. 55
B69: Chi phí tạo nhu cầu | E69: triệu USD | F69: =IF(F$61="","",INDEX('Dữ liệu biểu đồ'!$C$81:$I$81,F$61-2019)) -> 3.592 | G69: =IF(G$61="","",INDEX('Dữ liệu biểu đồ'!$C$81:$I$81,G$61-2019)) -> 3.114 | H69: =IF(H$61="","",INDEX('Dữ liệu biểu đồ'!$C$81:$I$81,H$61-2019)) -> 3.850 | I69: =IF(I$61="","",INDEX('Dữ liệu biểu đồ'!$C$81:$I$81,I$61-2019)) -> 4.060 | J69: =IF(J$61="","",INDEX('Dữ liệu biểu đồ'!$C$81:$I$81,J$61-2019)) -> 4.285 | K69: =IF(K$61="","",INDEX('Dữ liệu biểu đồ'!$C$81:$I$81,K$61-2019)) -> 4.689 | L69: =IF(L$61="","",INDEX('Dữ liệu biểu đồ'!$C$81:$I$81,L$61-2019)) -> 4.754
F70: =IF(F$61="","",IF(INDEX('Dữ liệu biểu đồ'!$J$81:$P$81,F$61-2019)="",INDEX('Dữ liệu biểu đồ'!$C$82:$I$82,F$61-2019)&"",HYPERLINK(INDEX('Dữ liệu biểu đồ'!$J$81:$P$81,F$61-2019),INDEX('Dữ liệu biểu đồ'!$C$82:$I$82,F$61-2019)))) -> tr. 56 | G70: =IF(G$61="","",IF(INDEX('Dữ liệu biểu đồ'!$J$81:$P$81,G$61-2019)="",INDEX('Dữ liệu biểu đồ'!$C$82:$I$82,G$61-2019)&"",HYPERLINK(INDEX('Dữ liệu biểu đồ'!$J$81:$P$81,G$61-2019),INDEX('Dữ liệu biểu đồ'!$C$82:$I$82,G$61-2019)))) -> tr. 57 | H70: =IF(H$61="","",IF(INDEX('Dữ liệu biểu đồ'!$J$81:$P$81,H$61-2019)="",INDEX('Dữ liệu biểu đồ'!$C$82:$I$82,H$61-2019)&"",HYPERLINK(INDEX('Dữ liệu biểu đồ'!$J$81:$P$81,H$61-2019),INDEX('Dữ liệu biểu đồ'!$C$82:$I$82,H$61-2019)))) -> tr. 56 | I70: =IF(I$61="","",IF(INDEX('Dữ liệu biểu đồ'!$J$81:$P$81,I$61-2019)="",INDEX('Dữ liệu biểu đồ'!$C$82:$I$82,I$61-2019)&"",HYPERLINK(INDEX('Dữ liệu biểu đồ'!$J$81:$P$81,I$61-2019),INDEX('Dữ liệu biểu đồ'!$C$82:$I$82,I$61-2019)))) -> tr. 55 | J70: =IF(J$61="","",IF(INDEX('Dữ liệu biểu đồ'!$J$81:$P$81,J$61-2019)="",INDEX('Dữ liệu biểu đồ'!$C$82:$I$82,J$61-2019)&"",HYPERLINK(INDEX('Dữ liệu biểu đồ'!$J$81:$P$81,J$61-2019),INDEX('Dữ liệu biểu đồ'!$C$82:$I$82,J$61-2019)))) -> tr. 57 | K70: =IF(K$61="","",IF(INDEX('Dữ liệu biểu đồ'!$J$81:$P$81,K$61-2019)="",INDEX('Dữ liệu biểu đồ'!$C$82:$I$82,K$61-2019)&"",HYPERLINK(INDEX('Dữ liệu biểu đồ'!$J$81:$P$81,K$61-2019),INDEX('Dữ liệu biểu đồ'!$C$82:$I$82,K$61-2019)))) -> tr. 56 | L70: =IF(L$61="","",IF(INDEX('Dữ liệu biểu đồ'!$J$81:$P$81,L$61-2019)="",INDEX('Dữ liệu biểu đồ'!$C$82:$I$82,L$61-2019)&"",HYPERLINK(INDEX('Dữ liệu biểu đồ'!$J$81:$P$81,L$61-2019),INDEX('Dữ liệu biểu đồ'!$C$82:$I$82,L$61-2019)))) -> tr. 55
B71: Chi phí vận hành chung | E71: triệu USD | F71: =IF(F$61="","",INDEX('Dữ liệu biểu đồ'!$C$83:$I$83,F$61-2019)) -> 9.534 | G71: =IF(G$61="","",INDEX('Dữ liệu biểu đồ'!$C$83:$I$83,G$61-2019)) -> 9.911 | H71: =IF(H$61="","",INDEX('Dữ liệu biểu đồ'!$C$83:$I$83,H$61-2019)) -> 10.954 | I71: =IF(I$61="","",INDEX('Dữ liệu biểu đồ'!$C$83:$I$83,I$61-2019)) -> 12.317 | J71: =IF(J$61="","",INDEX('Dữ liệu biểu đồ'!$C$83:$I$83,J$61-2019)) -> 12.291 | K71: =IF(K$61="","",INDEX('Dữ liệu biểu đồ'!$C$83:$I$83,K$61-2019)) -> 11.399 | L71: =IF(L$61="","",INDEX('Dữ liệu biểu đồ'!$C$83:$I$83,L$61-2019)) -> 11.360
F72: =IF(F$61="","",IF(INDEX('Dữ liệu biểu đồ'!$J$83:$P$83,F$61-2019)="",INDEX('Dữ liệu biểu đồ'!$C$84:$I$84,F$61-2019)&"",HYPERLINK(INDEX('Dữ liệu biểu đồ'!$J$83:$P$83,F$61-2019),INDEX('Dữ liệu biểu đồ'!$C$84:$I$84,F$61-2019)))) -> tr. 56 | G72: =IF(G$61="","",IF(INDEX('Dữ liệu biểu đồ'!$J$83:$P$83,G$61-2019)="",INDEX('Dữ liệu biểu đồ'!$C$84:$I$84,G$61-2019)&"",HYPERLINK(INDEX('Dữ liệu biểu đồ'!$J$83:$P$83,G$61-2019),INDEX('Dữ liệu biểu đồ'!$C$84:$I$84,G$61-2019)))) -> tr. 57 | H72: =IF(H$61="","",IF(INDEX('Dữ liệu biểu đồ'!$J$83:$P$83,H$61-2019)="",INDEX('Dữ liệu biểu đồ'!$C$84:$I$84,H$61-2019)&"",HYPERLINK(INDEX('Dữ liệu biểu đồ'!$J$83:$P$83,H$61-2019),INDEX('Dữ liệu biểu đồ'!$C$84:$I$84,H$61-2019)))) -> tr. 56 | I72: =IF(I$61="","",IF(INDEX('Dữ liệu biểu đồ'!$J$83:$P$83,I$61-2019)="",INDEX('Dữ liệu biểu đồ'!$C$84:$I$84,I$61-2019)&"",HYPERLINK(INDEX('Dữ liệu biểu đồ'!$J$83:$P$83,I$61-2019),INDEX('Dữ liệu biểu đồ'!$C$84:$I$84,I$61-2019)))) -> tr. 55 | J72: =IF(J$61="","",IF(INDEX('Dữ liệu biểu đồ'!$J$83:$P$83,J$61-2019)="",INDEX('Dữ liệu biểu đồ'!$C$84:$I$84,J$61-2019)&"",HYPERLINK(INDEX('Dữ liệu biểu đồ'!$J$83:$P$83,J$61-2019),INDEX('Dữ liệu biểu đồ'!$C$84:$I$84,J$61-2019)))) -> tr. 57 | K72: =IF(K$61="","",IF(INDEX('Dữ liệu biểu đồ'!$J$83:$P$83,K$61-2019)="",INDEX('Dữ liệu biểu đồ'!$C$84:$I$84,K$61-2019)&"",HYPERLINK(INDEX('Dữ liệu biểu đồ'!$J$83:$P$83,K$61-2019),INDEX('Dữ liệu biểu đồ'!$C$84:$I$84,K$61-2019)))) -> tr. 56 | L72: =IF(L$61="","",IF(INDEX('Dữ liệu biểu đồ'!$J$83:$P$83,L$61-2019)="",INDEX('Dữ liệu biểu đồ'!$C$84:$I$84,L$61-2019)&"",HYPERLINK(INDEX('Dữ liệu biểu đồ'!$J$83:$P$83,L$61-2019),INDEX('Dữ liệu biểu đồ'!$C$84:$I$84,L$61-2019)))) -> tr. 55
B73: Tổng chi phí bán hàng và quản lý | E73: triệu USD | F73: =IF(F$61="","",INDEX('Dữ liệu biểu đồ'!$C$85:$I$85,F$61-2019)) -> 13.126 | G73: =IF(G$61="","",INDEX('Dữ liệu biểu đồ'!$C$85:$I$85,G$61-2019)) -> 13.025 | H73: =IF(H$61="","",INDEX('Dữ liệu biểu đồ'!$C$85:$I$85,H$61-2019)) -> 14.804 | I73: =IF(I$61="","",INDEX('Dữ liệu biểu đồ'!$C$85:$I$85,I$61-2019)) -> 16.377 | J73: =IF(J$61="","",INDEX('Dữ liệu biểu đồ'!$C$85:$I$85,J$61-2019)) -> 16.576 | K73: =IF(K$61="","",INDEX('Dữ liệu biểu đồ'!$C$85:$I$85,K$61-2019)) -> 16.088 | L73: =IF(L$61="","",INDEX('Dữ liệu biểu đồ'!$C$85:$I$85,L$61-2019)) -> 16.114
F74: =IF(F$61="","",IF(INDEX('Dữ liệu biểu đồ'!$J$85:$P$85,F$61-2019)="",INDEX('Dữ liệu biểu đồ'!$C$86:$I$86,F$61-2019)&"",HYPERLINK(INDEX('Dữ liệu biểu đồ'!$J$85:$P$85,F$61-2019),INDEX('Dữ liệu biểu đồ'!$C$86:$I$86,F$61-2019)))) -> tr. 56 | G74: =IF(G$61="","",IF(INDEX('Dữ liệu biểu đồ'!$J$85:$P$85,G$61-2019)="",INDEX('Dữ liệu biểu đồ'!$C$86:$I$86,G$61-2019)&"",HYPERLINK(INDEX('Dữ liệu biểu đồ'!$J$85:$P$85,G$61-2019),INDEX('Dữ liệu biểu đồ'!$C$86:$I$86,G$61-2019)))) -> tr. 57 | H74: =IF(H$61="","",IF(INDEX('Dữ liệu biểu đồ'!$J$85:$P$85,H$61-2019)="",INDEX('Dữ liệu biểu đồ'!$C$86:$I$86,H$61-2019)&"",HYPERLINK(INDEX('Dữ liệu biểu đồ'!$J$85:$P$85,H$61-2019),INDEX('Dữ liệu biểu đồ'!$C$86:$I$86,H$61-2019)))) -> tr. 56 | I74: =IF(I$61="","",IF(INDEX('Dữ liệu biểu đồ'!$J$85:$P$85,I$61-2019)="",INDEX('Dữ liệu biểu đồ'!$C$86:$I$86,I$61-2019)&"",HYPERLINK(INDEX('Dữ liệu biểu đồ'!$J$85:$P$85,I$61-2019),INDEX('Dữ liệu biểu đồ'!$C$86:$I$86,I$61-2019)))) -> tr. 55 | J74: =IF(J$61="","",IF(INDEX('Dữ liệu biểu đồ'!$J$85:$P$85,J$61-2019)="",INDEX('Dữ liệu biểu đồ'!$C$86:$I$86,J$61-2019)&"",HYPERLINK(INDEX('Dữ liệu biểu đồ'!$J$85:$P$85,J$61-2019),INDEX('Dữ liệu biểu đồ'!$C$86:$I$86,J$61-2019)))) -> tr. 57 | K74: =IF(K$61="","",IF(INDEX('Dữ liệu biểu đồ'!$J$85:$P$85,K$61-2019)="",INDEX('Dữ liệu biểu đồ'!$C$86:$I$86,K$61-2019)&"",HYPERLINK(INDEX('Dữ liệu biểu đồ'!$J$85:$P$85,K$61-2019),INDEX('Dữ liệu biểu đồ'!$C$86:$I$86,K$61-2019)))) -> tr. 56 | L74: =IF(L$61="","",IF(INDEX('Dữ liệu biểu đồ'!$J$85:$P$85,L$61-2019)="",INDEX('Dữ liệu biểu đồ'!$C$86:$I$86,L$61-2019)&"",HYPERLINK(INDEX('Dữ liệu biểu đồ'!$J$85:$P$85,L$61-2019),INDEX('Dữ liệu biểu đồ'!$C$86:$I$86,L$61-2019)))) -> tr. 55
B75: Chi phí (thu nhập) lãi thuần | E75: triệu USD | F75: =IF(F$61="","",INDEX('Dữ liệu biểu đồ'!$C$87:$I$87,F$61-2019)) -> 89 | G75: =IF(G$61="","",INDEX('Dữ liệu biểu đồ'!$C$87:$I$87,G$61-2019)) -> 262 | H75: =IF(H$61="","",INDEX('Dữ liệu biểu đồ'!$C$87:$I$87,H$61-2019)) -> 205 | I75: =IF(I$61="","",INDEX('Dữ liệu biểu đồ'!$C$87:$I$87,I$61-2019)) -> (6) | J75: =IF(J$61="","",INDEX('Dữ liệu biểu đồ'!$C$87:$I$87,J$61-2019)) -> (161) | K75: =IF(K$61="","",INDEX('Dữ liệu biểu đồ'!$C$87:$I$87,K$61-2019)) -> (107) | L75: =IF(L$61="","",INDEX('Dữ liệu biểu đồ'!$C$87:$I$87,L$61-2019)) -> (50)
F76: =IF(F$61="","",IF(INDEX('Dữ liệu biểu đồ'!$J$87:$P$87,F$61-2019)="",INDEX('Dữ liệu biểu đồ'!$C$88:$I$88,F$61-2019)&"",HYPERLINK(INDEX('Dữ liệu biểu đồ'!$J$87:$P$87,F$61-2019),INDEX('Dữ liệu biểu đồ'!$C$88:$I$88,F$61-2019)))) -> tr. 56 | G76: =IF(G$61="","",IF(INDEX('Dữ liệu biểu đồ'!$J$87:$P$87,G$61-2019)="",INDEX('Dữ liệu biểu đồ'!$C$88:$I$88,G$61-2019)&"",HYPERLINK(INDEX('Dữ liệu biểu đồ'!$J$87:$P$87,G$61-2019),INDEX('Dữ liệu biểu đồ'!$C$88:$I$88,G$61-2019)))) -> tr. 57 | H76: =IF(H$61="","",IF(INDEX('Dữ liệu biểu đồ'!$J$87:$P$87,H$61-2019)="",INDEX('Dữ liệu biểu đồ'!$C$88:$I$88,H$61-2019)&"",HYPERLINK(INDEX('Dữ liệu biểu đồ'!$J$87:$P$87,H$61-2019),INDEX('Dữ liệu biểu đồ'!$C$88:$I$88,H$61-2019)))) -> tr. 56 | I76: =IF(I$61="","",IF(INDEX('Dữ liệu biểu đồ'!$J$87:$P$87,I$61-2019)="",INDEX('Dữ liệu biểu đồ'!$C$88:$I$88,I$61-2019)&"",HYPERLINK(INDEX('Dữ liệu biểu đồ'!$J$87:$P$87,I$61-2019),INDEX('Dữ liệu biểu đồ'!$C$88:$I$88,I$61-2019)))) -> tr. 55 | J76: =IF(J$61="","",IF(INDEX('Dữ liệu biểu đồ'!$J$87:$P$87,J$61-2019)="",INDEX('Dữ liệu biểu đồ'!$C$88:$I$88,J$61-2019)&"",HYPERLINK(INDEX('Dữ liệu biểu đồ'!$J$87:$P$87,J$61-2019),INDEX('Dữ liệu biểu đồ'!$C$88:$I$88,J$61-2019)))) -> tr. 57 | K76: =IF(K$61="","",IF(INDEX('Dữ liệu biểu đồ'!$J$87:$P$87,K$61-2019)="",INDEX('Dữ liệu biểu đồ'!$C$88:$I$88,K$61-2019)&"",HYPERLINK(INDEX('Dữ liệu biểu đồ'!$J$87:$P$87,K$61-2019),INDEX('Dữ liệu biểu đồ'!$C$88:$I$88,K$61-2019)))) -> tr. 56 | L76: =IF(L$61="","",IF(INDEX('Dữ liệu biểu đồ'!$J$87:$P$87,L$61-2019)="",INDEX('Dữ liệu biểu đồ'!$C$88:$I$88,L$61-2019)&"",HYPERLINK(INDEX('Dữ liệu biểu đồ'!$J$87:$P$87,L$61-2019),INDEX('Dữ liệu biểu đồ'!$C$88:$I$88,L$61-2019)))) -> tr. 55
B77: Chi phí (thu nhập) khác thuần | E77: triệu USD | F77: =IF(F$61="","",INDEX('Dữ liệu biểu đồ'!$C$89:$I$89,F$61-2019)) -> 139 | G77: =IF(G$61="","",INDEX('Dữ liệu biểu đồ'!$C$89:$I$89,G$61-2019)) -> 14 | H77: =IF(H$61="","",INDEX('Dữ liệu biểu đồ'!$C$89:$I$89,H$61-2019)) -> (181) | I77: =IF(I$61="","",INDEX('Dữ liệu biểu đồ'!$C$89:$I$89,I$61-2019)) -> (280) | J77: =IF(J$61="","",INDEX('Dữ liệu biểu đồ'!$C$89:$I$89,J$61-2019)) -> (228) | K77: =IF(K$61="","",INDEX('Dữ liệu biểu đồ'!$C$89:$I$89,K$61-2019)) -> (76) | L77: =IF(L$61="","",INDEX('Dữ liệu biểu đồ'!$C$89:$I$89,L$61-2019)) -> (53)
F78: =IF(F$61="","",IF(INDEX('Dữ liệu biểu đồ'!$J$89:$P$89,F$61-2019)="",INDEX('Dữ liệu biểu đồ'!$C$90:$I$90,F$61-2019)&"",HYPERLINK(INDEX('Dữ liệu biểu đồ'!$J$89:$P$89,F$61-2019),INDEX('Dữ liệu biểu đồ'!$C$90:$I$90,F$61-2019)))) -> tr. 56 | G78: =IF(G$61="","",IF(INDEX('Dữ liệu biểu đồ'!$J$89:$P$89,G$61-2019)="",INDEX('Dữ liệu biểu đồ'!$C$90:$I$90,G$61-2019)&"",HYPERLINK(INDEX('Dữ liệu biểu đồ'!$J$89:$P$89,G$61-2019),INDEX('Dữ liệu biểu đồ'!$C$90:$I$90,G$61-2019)))) -> tr. 57 | H78: =IF(H$61="","",IF(INDEX('Dữ liệu biểu đồ'!$J$89:$P$89,H$61-2019)="",INDEX('Dữ liệu biểu đồ'!$C$90:$I$90,H$61-2019)&"",HYPERLINK(INDEX('Dữ liệu biểu đồ'!$J$89:$P$89,H$61-2019),INDEX('Dữ liệu biểu đồ'!$C$90:$I$90,H$61-2019)))) -> tr. 56 | I78: =IF(I$61="","",IF(INDEX('Dữ liệu biểu đồ'!$J$89:$P$89,I$61-2019)="",INDEX('Dữ liệu biểu đồ'!$C$90:$I$90,I$61-2019)&"",HYPERLINK(INDEX('Dữ liệu biểu đồ'!$J$89:$P$89,I$61-2019),INDEX('Dữ liệu biểu đồ'!$C$90:$I$90,I$61-2019)))) -> tr. 55 | J78: =IF(J$61="","",IF(INDEX('Dữ liệu biểu đồ'!$J$89:$P$89,J$61-2019)="",INDEX('Dữ liệu biểu đồ'!$C$90:$I$90,J$61-2019)&"",HYPERLINK(INDEX('Dữ liệu biểu đồ'!$J$89:$P$89,J$61-2019),INDEX('Dữ liệu biểu đồ'!$C$90:$I$90,J$61-2019)))) -> tr. 57 | K78: =IF(K$61="","",IF(INDEX('Dữ liệu biểu đồ'!$J$89:$P$89,K$61-2019)="",INDEX('Dữ liệu biểu đồ'!$C$90:$I$90,K$61-2019)&"",HYPERLINK(INDEX('Dữ liệu biểu đồ'!$J$89:$P$89,K$61-2019),INDEX('Dữ liệu biểu đồ'!$C$90:$I$90,K$61-2019)))) -> tr. 56 | L78: =IF(L$61="","",IF(INDEX('Dữ liệu biểu đồ'!$J$89:$P$89,L$61-2019)="",INDEX('Dữ liệu biểu đồ'!$C$90:$I$90,L$61-2019)&"",HYPERLINK(INDEX('Dữ liệu biểu đồ'!$J$89:$P$89,L$61-2019),INDEX('Dữ liệu biểu đồ'!$C$90:$I$90,L$61-2019)))) -> tr. 55
B79: Lợi nhuận trước thuế | E79: triệu USD | F79: =IF(F$61="","",INDEX('Dữ liệu biểu đồ'!$C$91:$I$91,F$61-2019)) -> 2.887 | G79: =IF(G$61="","",INDEX('Dữ liệu biểu đồ'!$C$91:$I$91,G$61-2019)) -> 6.661 | H79: =IF(H$61="","",INDEX('Dữ liệu biểu đồ'!$C$91:$I$91,H$61-2019)) -> 6.651 | I79: =IF(I$61="","",INDEX('Dữ liệu biểu đồ'!$C$91:$I$91,I$61-2019)) -> 6.201 | J79: =IF(J$61="","",INDEX('Dữ liệu biểu đồ'!$C$91:$I$91,J$61-2019)) -> 6.700 | K79: =IF(K$61="","",INDEX('Dữ liệu biểu đồ'!$C$91:$I$91,K$61-2019)) -> 3.885 | L79: =IF(L$61="","",INDEX('Dữ liệu biểu đồ'!$C$91:$I$91,L$61-2019)) -> 3.900
F80: =IF(F$61="","",IF(INDEX('Dữ liệu biểu đồ'!$J$91:$P$91,F$61-2019)="",INDEX('Dữ liệu biểu đồ'!$C$92:$I$92,F$61-2019)&"",HYPERLINK(INDEX('Dữ liệu biểu đồ'!$J$91:$P$91,F$61-2019),INDEX('Dữ liệu biểu đồ'!$C$92:$I$92,F$61-2019)))) -> tr. 56 | G80: =IF(G$61="","",IF(INDEX('Dữ liệu biểu đồ'!$J$91:$P$91,G$61-2019)="",INDEX('Dữ liệu biểu đồ'!$C$92:$I$92,G$61-2019)&"",HYPERLINK(INDEX('Dữ liệu biểu đồ'!$J$91:$P$91,G$61-2019),INDEX('Dữ liệu biểu đồ'!$C$92:$I$92,G$61-2019)))) -> tr. 57 | H80: =IF(H$61="","",IF(INDEX('Dữ liệu biểu đồ'!$J$91:$P$91,H$61-2019)="",INDEX('Dữ liệu biểu đồ'!$C$92:$I$92,H$61-2019)&"",HYPERLINK(INDEX('Dữ liệu biểu đồ'!$J$91:$P$91,H$61-2019),INDEX('Dữ liệu biểu đồ'!$C$92:$I$92,H$61-2019)))) -> tr. 56 | I80: =IF(I$61="","",IF(INDEX('Dữ liệu biểu đồ'!$J$91:$P$91,I$61-2019)="",INDEX('Dữ liệu biểu đồ'!$C$92:$I$92,I$61-2019)&"",HYPERLINK(INDEX('Dữ liệu biểu đồ'!$J$91:$P$91,I$61-2019),INDEX('Dữ liệu biểu đồ'!$C$92:$I$92,I$61-2019)))) -> tr. 55 | J80: =IF(J$61="","",IF(INDEX('Dữ liệu biểu đồ'!$J$91:$P$91,J$61-2019)="",INDEX('Dữ liệu biểu đồ'!$C$92:$I$92,J$61-2019)&"",HYPERLINK(INDEX('Dữ liệu biểu đồ'!$J$91:$P$91,J$61-2019),INDEX('Dữ liệu biểu đồ'!$C$92:$I$92,J$61-2019)))) -> tr. 57 | K80: =IF(K$61="","",IF(INDEX('Dữ liệu biểu đồ'!$J$91:$P$91,K$61-2019)="",INDEX('Dữ liệu biểu đồ'!$C$92:$I$92,K$61-2019)&"",HYPERLINK(INDEX('Dữ liệu biểu đồ'!$J$91:$P$91,K$61-2019),INDEX('Dữ liệu biểu đồ'!$C$92:$I$92,K$61-2019)))) -> tr. 56 | L80: =IF(L$61="","",IF(INDEX('Dữ liệu biểu đồ'!$J$91:$P$91,L$61-2019)="",INDEX('Dữ liệu biểu đồ'!$C$92:$I$92,L$61-2019)&"",HYPERLINK(INDEX('Dữ liệu biểu đồ'!$J$91:$P$91,L$61-2019),INDEX('Dữ liệu biểu đồ'!$C$92:$I$92,L$61-2019)))) -> tr. 55
B81: Chi phí thuế thu nhập | E81: triệu USD | F81: =IF(F$61="","",INDEX('Dữ liệu biểu đồ'!$C$93:$I$93,F$61-2019)) -> 348 | G81: =IF(G$61="","",INDEX('Dữ liệu biểu đồ'!$C$93:$I$93,G$61-2019)) -> 934 | H81: =IF(H$61="","",INDEX('Dữ liệu biểu đồ'!$C$93:$I$93,H$61-2019)) -> 605 | I81: =IF(I$61="","",INDEX('Dữ liệu biểu đồ'!$C$93:$I$93,I$61-2019)) -> 1.131 | J81: =IF(J$61="","",INDEX('Dữ liệu biểu đồ'!$C$93:$I$93,J$61-2019)) -> 1.000 | K81: =IF(K$61="","",INDEX('Dữ liệu biểu đồ'!$C$93:$I$93,K$61-2019)) -> 666 | L81: =IF(L$61="","",INDEX('Dữ liệu biểu đồ'!$C$93:$I$93,L$61-2019)) -> 792
F82: =IF(F$61="","",IF(INDEX('Dữ liệu biểu đồ'!$J$93:$P$93,F$61-2019)="",INDEX('Dữ liệu biểu đồ'!$C$94:$I$94,F$61-2019)&"",HYPERLINK(INDEX('Dữ liệu biểu đồ'!$J$93:$P$93,F$61-2019),INDEX('Dữ liệu biểu đồ'!$C$94:$I$94,F$61-2019)))) -> tr. 56 | G82: =IF(G$61="","",IF(INDEX('Dữ liệu biểu đồ'!$J$93:$P$93,G$61-2019)="",INDEX('Dữ liệu biểu đồ'!$C$94:$I$94,G$61-2019)&"",HYPERLINK(INDEX('Dữ liệu biểu đồ'!$J$93:$P$93,G$61-2019),INDEX('Dữ liệu biểu đồ'!$C$94:$I$94,G$61-2019)))) -> tr. 57 | H82: =IF(H$61="","",IF(INDEX('Dữ liệu biểu đồ'!$J$93:$P$93,H$61-2019)="",INDEX('Dữ liệu biểu đồ'!$C$94:$I$94,H$61-2019)&"",HYPERLINK(INDEX('Dữ liệu biểu đồ'!$J$93:$P$93,H$61-2019),INDEX('Dữ liệu biểu đồ'!$C$94:$I$94,H$61-2019)))) -> tr. 56 | I82: =IF(I$61="","",IF(INDEX('Dữ liệu biểu đồ'!$J$93:$P$93,I$61-2019)="",INDEX('Dữ liệu biểu đồ'!$C$94:$I$94,I$61-2019)&"",HYPERLINK(INDEX('Dữ liệu biểu đồ'!$J$93:$P$93,I$61-2019),INDEX('Dữ liệu biểu đồ'!$C$94:$I$94,I$61-2019)))) -> tr. 55 | J82: =IF(J$61="","",IF(INDEX('Dữ liệu biểu đồ'!$J$93:$P$93,J$61-2019)="",INDEX('Dữ liệu biểu đồ'!$C$94:$I$94,J$61-2019)&"",HYPERLINK(INDEX('Dữ liệu biểu đồ'!$J$93:$P$93,J$61-2019),INDEX('Dữ liệu biểu đồ'!$C$94:$I$94,J$61-2019)))) -> tr. 57 | K82: =IF(K$61="","",IF(INDEX('Dữ liệu biểu đồ'!$J$93:$P$93,K$61-2019)="",INDEX('Dữ liệu biểu đồ'!$C$94:$I$94,K$61-2019)&"",HYPERLINK(INDEX('Dữ liệu biểu đồ'!$J$93:$P$93,K$61-2019),INDEX('Dữ liệu biểu đồ'!$C$94:$I$94,K$61-2019)))) -> tr. 56 | L82: =IF(L$61="","",IF(INDEX('Dữ liệu biểu đồ'!$J$93:$P$93,L$61-2019)="",INDEX('Dữ liệu biểu đồ'!$C$94:$I$94,L$61-2019)&"",HYPERLINK(INDEX('Dữ liệu biểu đồ'!$J$93:$P$93,L$61-2019),INDEX('Dữ liệu biểu đồ'!$C$94:$I$94,L$61-2019)))) -> tr. 55
B83: Lợi nhuận sau thuế | E83: triệu USD | F83: =IF(F$61="","",INDEX('Dữ liệu biểu đồ'!$C$95:$I$95,F$61-2019)) -> 2.539 | G83: =IF(G$61="","",INDEX('Dữ liệu biểu đồ'!$C$95:$I$95,G$61-2019)) -> 5.727 | H83: =IF(H$61="","",INDEX('Dữ liệu biểu đồ'!$C$95:$I$95,H$61-2019)) -> 6.046 | I83: =IF(I$61="","",INDEX('Dữ liệu biểu đồ'!$C$95:$I$95,I$61-2019)) -> 5.070 | J83: =IF(J$61="","",INDEX('Dữ liệu biểu đồ'!$C$95:$I$95,J$61-2019)) -> 5.700 | K83: =IF(K$61="","",INDEX('Dữ liệu biểu đồ'!$C$95:$I$95,K$61-2019)) -> 3.219 | L83: =IF(L$61="","",INDEX('Dữ liệu biểu đồ'!$C$95:$I$95,L$61-2019)) -> 3.108
...

Sheet Nguồn và phương pháp
B2: Nguồn và phương pháp
B4: Báo cáo Form 10‑K (SEC EDGAR) | D4: Phương pháp
B5: Form 10‑K FY2020, nộp ngày 24/07/2020, số 0000320187-20-000047 | D5: – Số liệu của mỗi năm tài chính được lấy từ báo cáo 10‑K của chính năm đó. Mỗi báo cáo đều in kèm số của năm trước để so sánh, và tăng trưởng được tính với chính số năm trước này, giống cách NIKE tự tính. Ví dụ: tăng trưởng doanh thu FY2026 tính với doanh thu FY2025 in trong 10‑K FY2026.
B6: Form 10‑K FY2021, nộp ngày 20/07/2021, số 0000320187-21-000028 | D6: – Các số trên báo cáo tài chính được lấy từ dữ liệu XBRL đi kèm mỗi báo cáo 10‑K, sau đó đối chiếu với dữ liệu XBRL do SEC công bố và với các bảng trong phần MD&A.
B7: Form 10‑K FY2022, nộp ngày 21/07/2022, số 0000320187-22-000038 | D7: – Các chỉ tiêu chỉ có trong phần MD&A (tăng trưởng loại trừ tỷ giá, doanh số Digital) không có dữ liệu XBRL để đối chiếu, nên được đọc lại thêm một lần ngay trên trang 10‑K. Ảnh chụp từng chỗ có ở trang “Đối chiếu 35 số” trên dashboard web.
B8: Form 10‑K FY2023, nộp ngày 20/07/2023, số 0000320187-23-000039 | D8: – Các chỉ số do nhóm tự tính dùng đúng công thức ở sheet 04 của bộ dữ liệu Excel. Mỗi lần cập nhật đều kiểm tra lại các phép cộng trừ, chẳng hạn doanh thu trừ giá vốn phải bằng lợi nhuận gộp.
B9: Form 10‑K FY2024, nộp ngày 25/07/2024, số 0000320187-24-000044 | D9: – Số liệu nào NIKE không công bố thì ghi “Không công bố”, không điền số 0.
B10: Form 10‑K FY2025, nộp ngày 17/07/2025, số 0000320187-25-000047
B11: Form 10‑K FY2026, nộp ngày 15/07/2026, số 0000320187-26-000088
B13: Tình trạng dữ liệu | D13: Liên kết
B14: 203 số liệu báo cáo: 202 khớp nguồn chính thức, 1 không được NIKE công bố. Dữ liệu trích xuất ngày 23/10/2026. | D14: Dashboard web
D15: Bộ dữ liệu Excel (đầy đủ nguồn từng số)
B16: Sản phẩm học tập của sinh viên, không liên quan đến NIKE, Inc. | D16: Đối chiếu 35 số trên trang 10‑K (ảnh chụp)

Sheet Dữ liệu biểu đồ
A1: Dữ liệu cho biểu đồ và tóm tắt
A2: Lấy từ site/data/nike-financials.json (cùng dữ liệu với dashboard web). Slicer “Năm tài chính” lọc bảng tblNam; biểu đồ và tóm tắt chỉ dùng các năm đang hiện. Không sửa sheet này.
A4: Năm tài chính | B4: Năm | C4: Tỷ trọng NIKE Direct | D4: Tỷ trọng bán buôn | E4: Tỷ trọng Global Brand Divisions | F4: NIKE Direct (tỷ USD) | G4: Bán buôn (tỷ USD) | H4: Tăng trưởng NIKE Direct theo báo cáo | I4: Tăng trưởng bán buôn theo báo cáo | J4: Tăng trưởng NIKE Direct loại trừ tỷ giá | K4: Tăng trưởng bán buôn loại trừ tỷ giá | L4: NIKE Direct (biểu đồ tăng trưởng) | M4: Bán buôn (biểu đồ tăng trưởng) | N4: NIKE Brand Digital (tỷ USD) | O4: Doanh thu NIKE, Inc. (tỷ USD) | P4: Biên lợi nhuận gộp | Q4: Vận hành chung / doanh thu | R4: Tạo nhu cầu / doanh thu | S4: Tổng SG&A / doanh thu | T4: Biên EBIT | U4: Hàng tồn kho (tỷ USD) | V4: Số ngày tồn kho bình quân | W4: Tỷ trọng NIKE Direct (chữ) | X4: Tỷ trọng bán buôn (chữ) | Y4: NIKE Direct (chữ) | Z4: Bán buôn (chữ) | AA4: Doanh thu (chữ) | AB4: Biên lợi nhuận gộp (chữ) | AC4: Biên EBIT (chữ) | AD4: Hàng tồn kho (chữ)
A5: FY2020 | B5: 2020 | C5: 0.34812191 | D5: 0.65103464 | E5: 0.00084345479 | F5: 12.382 | G5: 23.156 | H5: 0.053518251 | I5: -0.089171223 | J5: 0.08 | K5: -0.07 | L5: =IF($C$20="cn",J5,H5) -> 0.053518251 | M5: =IF($C$20="cn",K5,I5) -> -0.089171223 | N5: 5.5 | O5: 37.403 | P5: 0.43421651 | Q5: 0.25489934 | R5: 0.096035077 | S5: 0.35093442 | T5: 0.07956581 | U5: 7.367 | V5: 112.01647 | W5: 34,8% | X5: 65,1% | Y5: 12,4 | Z5: 23,2 | AA5: 37,4 | AB5: 43,4% | AC5: 8,0% | AD5: 7,4
A6: FY2021 | B6: 2021 | C6: 0.38706169 | D6: 0.6123472 | E6: 0.00059111437 | F6: 16.37 | G6: 25.898 | H6: 0.32208044 | I6: 0.11841423 | J6: 0.3 | K6: 0.1 | L6: =IF($C$20="cn",J6,H6) -> 0.32208044 | M6: =IF($C$20="cn",K6,I6) -> 0.11841423 | N6: 9.1 | O6: 44.538 | P6: 0.44820154 | Q6: 0.22252908 | R6: 0.069917823 | S6: 0.2924469 | T6: 0.1554403 | U6: 6.854 | V6: 105.60435 | W6: 38,7% | X6: 61,2% | Y6: 16,4 | Z6: 25,9 | AA6: 44,5 | AB6: 44,8% | AC6: 15,5% | AD6: 6,9
A7: FY2022 | B7: 2022 | C7: 0.42141507 | D7: 0.5762895 | E7: 0.0022954361 | F7: 18.726 | G7: 25.608 | H7: 0.14392181 | I7: -0.011197776 | J7: 0.15 | K7: -0.01 | L7: =IF($C$20="cn",J7,H7) -> 0.14392181 | M7: =IF($C$20="cn",K7,I7) -> -0.011197776 | N7: 10.7 | O7: 46.71 | P7: 0.45983729 | Q7: 0.23451081 | R7: 0.082423464 | S7: 0.31693428 | T7: 0.14677799 | U7: 8.42 | V7: 110.47937 | W7: 42,1% | X7: 57,6% | Y7: 18,7 | Z7: 25,6 | AA7: 46,7 | AB7: 46,0% | AC7: 14,7% | AD7: 8,4
A8: FY2023 | B8: 2023 | C8: 0.43697065 | D8: 0.56183992 | E8: 0.0011894264 | F8: 21.308 | G8: 27.397 | H8: 0.13788316 | I8: 0.069860981 | J8: 0.2 | K8: 0.14 | L8: =IF($C$20="cn",J8,H8) -> 0.13788316 | M8: =IF($C$20="cn",K8,I8) -> 0.069860981 | N8: 12.6 | O8: 51.217 | P8: 0.43524611 | Q8: 0.24048656 | R8: 0.079270555 | S8: 0.31975711 | T8: 0.12095593 | U8: 8.454 | V8: 106.46517 | W8: 43,7% | X8: 56,2% | Y8: 21,3 | Z8: 27,4 | AA8: 51,2 | AB8: 43,5% | AC8: 12,1% | AD8: 8,5
A9: FY2024 | B9: 2024 | C9: 0.43629618 | D9: 0.56279145 | E9: 0.00091237176 | F9: 21.519 | G9: 27.758 | H9: 0.0099023841 | I9: 0.013176625 | J9: 0.01 | K9: 0.02 | L9: =IF($C$20="cn",J9,H9) -> 0.0099023841 | M9: =IF($C$20="cn",K9,I9) -> 0.013176625 | N9: 12.1 | O9: 51.362 | P9: 0.44560181 | Q9: 0.23930143 | R9: 0.083427437 | S9: 0.32272887 | T9: 0.12731202 | U9: 7.519 | V9: 102.37305 | W9: 43,6% | X9: 56,3% | Y9: 21,5 | Z9: 27,8 | AA9: 51,4 | AB9: 44,6% | AC9: 12,7% | AD9: 7,5
A10: FY2025 | B10: 2025 | C10: 0.42006978 | D10: 0.57885673 | E10: 0.0010734893 | F10: 18.783 | G10: 25.883 | H10: -0.12714345 | I10: -0.067548094 | J10: -0.12 | K10: -0.06 | L10: =IF($C$20="cn",J10,H10) -> -0.12714345 | M10: =IF($C$20="cn",K10,I10) -> -0.067548094 | N10: 9.6 | O10: 46.309 | P10: 0.42734674 | Q10: 0.24615086 | R10: 0.10125462 | S10: 0.34740547 | T10: 0.081582414 | U10: 7.489 | V10: 103.28293 | W10: 42,0% | X10: 57,9% | Y10: 18,8 | Z10: 25,9 | AA10: 46,3 | AB10: 42,7% | AC10: 8,2% | AD10: 7,5
A11: FY2026 | B11: 2026 | C11: 0.39184468 | D11: 0.60707178 | E11: 0.0010835434 | F11: 17.72 | G11: 27.453 | H11: -0.056593728 | I11: 0.060657574 | J11: -0.08 | K11: 0.04 | L11: =IF($C$20="cn",J11,H11) -> -0.056593728 | M11: =IF($C$20="cn",K11,I11) -> 0.060657574 | N11: 8.6 | O11: 46.398 | P11: 0.42913488 | Q11: 0.24483814 | R11: 0.10246131 | S11: 0.34729945 | T11: 0.082977715 | U11: 7.501 | V11: 103.28369 | W11: 39,2% | X11: 60,7% | Y11: 17,7 | Z11: 27,5 | AA11: 46,4 | AB11: 42,9% | AC11: 8,3% | AD11: 7,5
A14: Cơ sở tính tăng trưởng
A15: Theo báo cáo
A16: Loại trừ tỷ giá
A19: Biến phụ cho tóm tắt
B20: Cơ sở tăng trưởng | C20: =IF(AND(SUBTOTAL(103,A16)=1,SUBTOTAL(103,A15)=0),"cn","reported") -> reported
B21: Năm đầu | C21: =_xlfn.AGGREGATE(15,5,$B$5:$B$11,1) -> 2020
B22: Năm cuối | C22: =_xlfn.AGGREGATE(14,5,$B$5:$B$11,1) -> 2026
B23: Số năm | C23: =SUBTOTAL(103,$B$5:$B$11) -> 7
B24: Năm tỷ trọng Direct cao nhất | C24: =INDEX($B$5:$B$11,MATCH(_xlfn.AGGREGATE(14,5,$C$5:$C$11,1),$C$5:$C$11,0)) -> 2023
B25: Năm tỷ trọng Direct thấp nhất | C25: =INDEX($B$5:$B$11,MATCH(_xlfn.AGGREGATE(15,5,$C$5:$C$11,1),$C$5:$C$11,0)) -> 2020
B26: Năm biên EBIT cao nhất | C26: =INDEX($B$5:$B$11,MATCH(_xlfn.AGGREGATE(14,5,$T$5:$T$11,1),$T$5:$T$11,0)) -> 2021
B27: channels | C27: =IF($C$21=$C$22,"Trong FY"&$C$21&", NIKE Direct chiếm "&INDEX($W$5:$W$11,$C$21-2019)&" doanh thu NIKE Brand ("&INDEX($Y$5:$Y$11,$C$21-2019)&" tỷ USD), còn bán buôn chiếm "&INDEX($X$5:$X$11,$C$21-2019)&" ("&INDEX($Z$5:$Z$11,$C$21-2019)&" tỷ USD).","Tỷ trọng NIKE Direct trong doanh thu NIKE Brand là "&INDEX($W$5:$W$11,$C$21-2019)&" ở FY"&$C$21&" và "&INDEX($W$5:$W$11,$C$22-2019)&" ở FY"&$C$22&IF(AND($C$24<>$C$21,$C$24<>$C$22),", cao nhất "&INDEX($W$5:$W$11,$C$24-2019)&" (FY"&$C$24&")","")&IF(AND($C$25<>$C$21,$C$25<>$C$22),IF(AND($C$24<>$C$21,$C$24<>$C$22)," và thấp nhất ",", thấp nhất ")&INDEX($W$5:$W$11,$C$25-2019)&" (FY"&$C$25&")","")&". Doanh thu NIKE Direct đi từ "&INDEX($Y$5:$Y$11,$C$21-2019)&" đến "&INDEX($Y$5:$Y$11,$C$22-2019)&" tỷ USD, còn bán buôn từ "&INDEX($Z$5:$Z$11,$C$21-2019)&" đến "&INDEX($Z$5:$Z$11,$C$22-2019)&" tỷ USD.") -> Tỷ trọng NIKE Direct trong doanh thu NIKE Brand là 34,8% ở FY2020 và 39,2% ở FY2026, cao nhất 43,7% (FY2023). Doanh thu NIKE Direct đi từ 12,4 đến 17,7 tỷ USD, còn bán buôn từ 23,2 đến 27,5 tỷ USD.
B28: performance | C28: =IF($C$21=$C$22,"Trong FY"&$C$21&", doanh thu NIKE, Inc. là "&INDEX($AA$5:$AA$11,$C$21-2019)&" tỷ USD, biên lợi nhuận gộp "&INDEX($AB$5:$AB$11,$C$21-2019)&", biên EBIT (non‑GAAP) "&INDEX($AC$5:$AC$11,$C$21-2019)&", hàng tồn kho cuối kỳ "&INDEX($AD$5:$AD$11,$C$21-2019)&" tỷ USD.","Doanh thu NIKE, Inc. đi từ "&INDEX($AA$5:$AA$11,$C$21-2019)&" (FY"&$C$21&") đến "&INDEX($AA$5:$AA$11,$C$22-2019)&" tỷ USD (FY"&$C$22&"). Biên lợi nhuận gộp là "&INDEX($AB$5:$AB$11,$C$21-2019)&" (FY"&$C$21&") và "&INDEX($AB$5:$AB$11,$C$22-2019)&" (FY"&$C$22&"), còn biên EBIT (non‑GAAP) là "&INDEX($AC$5:$AC$11,$C$21-2019)&" (FY"&$C$21&") và "&INDEX($AC$5:$AC$11,$C$22-2019)&" (FY"&$C$22&")"&IF(AND($C$26<>$C$21,$C$26<>$C$22),", cao nhất "&INDEX($AC$5:$AC$11,$C$26-2019)&" (FY"&$C$26&")","")&". Hàng tồn kho cuối kỳ đi từ "&INDEX($AD$5:$AD$11,$C$21-2019)&" đến "&INDEX($AD$5:$AD$11,$C$22-2019)&" tỷ USD.") -> Doanh thu NIKE, Inc. đi từ 37,4 (FY2020) đến 46,4 tỷ USD (FY2026). Biên lợi nhuận gộp là 43,4% (FY2020) và 42,9% (FY2026), còn biên EBIT (non‑GAAP) là 8,0% (FY2020) và 8,3% (FY2026), cao nhất 15,5% (FY2021). Hàng tồn kho cuối kỳ đi từ 7,4 đến 7,5 tỷ USD.
